Workbook

Sheet Instrukcja
B1: Kalkulator Ceny w zł
B2: Pierwsze Zamówienia w 14 Dni™ · ile naprawdę kosztuje Cię jeden baton i za ile go sprzedać
B4: Jak to działa – 6 kroków
B5: 1. Przejdź do arkusza „Kalkulator”. Jest wypełniony przykładem: Batony owsiano-miodowe z rozdziału 4 Biblii.
B6: 2. Ceny w przykładzie to PRZYKŁADOWE CENY z polskiego supermarketu – wpisz swoje z paragonów.
B7: 3. Wypełniasz tylko ŻÓŁTE pola: cena opakowania, wielkość opakowania, ile zużyłaś do partii, liczba batonów z partii.
B8: 4. Dopisz koszt torebki i etykiety oraz inne koszty partii (np. papier do pieczenia).
B9: 5. Wybierz narzut (np. 120%). Kalkulator policzy koszt sztuki, cenę zaokrągloną w górę do 0,50 zł i zysk z partii.
B10: 6. Chcesz inną cenę? Wpisz ją w polu „Twoja cena”. Kalkulator przeliczy zysk dla Twojej ceny.
B12: Kolory pól
B13: Żółte pole = tu wpisujesz swoje dane.
B14: Białe pole = wynik liczony automatycznie. Nie nadpisuj go – są w nim formuły.
... B27: Instrukcja krok po kroku jest też w pliku PDF „Jak używać kalkulatora”.

Sheet Kalkulator
A1: Kalkulator Ceny w zł
A2: Przykład: Batony owsiano-miodowe (Biblia, rozdział 4) · PRZYKŁADOWE CENY, WPISZ SWOJE
A4: Nazwa przepisu | B4: Batony owsiano-miodowe
A5: Liczba batonów z jednej partii | B5: 12
A6: Waga jednego batona (g) – na etykietę | B6: 40
A8: 1. Składniki na jedną partię
A9: Składnik | B9: Cena opakowania (zł) | C9: Wielkość opakowania | D9: Jednostka | E9: Zużyte w partii | F9: Koszt w partii (zł) | G9: Na zamówienie (patrz pkt 5)
A10: Płatki owsiane | B10: 4.49 | C10: 500 | D10: g | E10: 180 | F10: =IF(AND(ISNUMBER(B10),ISNUMBER(C10),ISNUMBER(E10),N(C10)>0),B10/C10*E10,0) | G10: =IF(ISNUMBER(E10),E10*$B$54,"")
A11: Miód | B11: 17.99 | C11: 370 | D11: g | E11: 170 | F11: =IF(AND(ISNUMBER(B11),ISNUMBER(C11),ISNUMBER(E11),N(C11)>0),B11/C11*E11,0) | G11: =IF(ISNUMBER(E11),E11*$B$54,"")
A12: Masło orzechowe 100% | B12: 12.99 | C12: 350 | D12: g | E12: 65 | F12: =IF(AND(ISNUMBER(B12),ISNUMBER(C12),ISNUMBER(E12),N(C12)>0),B12/C12*E12,0) | G12: =IF(ISNUMBER(E12),E12*$B$54,"")
A13: Orzechy włoskie (siekane) | B13: 11.99 | C13: 200 | D13: g | E13: 60 | F13: =IF(AND(ISNUMBER(B13),ISNUMBER(C13),ISNUMBER(E13),N(C13)>0),B13/C13*E13,0) | G13: =IF(ISNUMBER(E13),E13*$B$54,"")
A14: Ekstrakt waniliowy | B14: 16.99 | C14: 50 | D14: ml | E14: 5 | F14: =IF(AND(ISNUMBER(B14),ISNUMBER(C14),ISNUMBER(E14),N(C14)>0),B14/C14*E14,0) | G14: =IF(ISNUMBER(E14),E14*$B$54,"")
A15: Sól | B15: 2.49 | C15: 1000 | D15: g | E15: 1 | F15: =IF(AND(ISNUMBER(B15),ISNUMBER(C15),ISNUMBER(E15),N(C15)>0),B15/C15*E15,0) | G15: =IF(ISNUMBER(E15),E15*$B$54,"")
A16: Odżywka białkowa (jeśli dodajesz) | B16: 89.99 | C16: 700 | D16: g | E16: 0 | F16: =IF(AND(ISNUMBER(B16),ISNUMBER(C16),ISNUMBER(E16),N(C16)>0),B16/C16*E16,0) | G16: =IF(ISNUMBER(E16),E16*$B$54,"")
F17: =IF(AND(ISNUMBER(B17),ISNUMBER(C17),ISNUMBER(E17),N(C17)>0),B17/C17*E17,0) | G17: =IF(ISNUMBER(E17),E17*$B$54,"")
F18: =IF(AND(ISNUMBER(B18),ISNUMBER(C18),ISNUMBER(E18),N(C18)>0),B18/C18*E18,0) | G18: =IF(ISNUMBER(E18),E18*$B$54,"")
F19: =IF(AND(ISNUMBER(B19),ISNUMBER(C19),ISNUMBER(E19),N(C19)>0),B19/C19*E19,0) | G19: =IF(ISNUMBER(E19),E19*$B$54,"")
F20: =IF(AND(ISNUMBER(B20),ISNUMBER(C20),ISNUMBER(E20),N(C20)>0),B20/C20*E20,0) | G20: =IF(ISNUMBER(E20),E20*$B$54,"")
F21: =IF(AND(ISNUMBER(B21),ISNUMBER(C21),ISNUMBER(E21),N(C21)>0),B21/C21*E21,0) | G21: =IF(ISNUMBER(E21),E21*$B$54,"")
A22: Suma składników na partię | F22: =SUM(F10:F21)
A24: 2. Opakowanie i etykieta (na jeden baton)
A25: Element | B25: Cena paczki (zł) | C25: Sztuk w paczce | E25: Ile na 1 baton | F25: Koszt na baton (zł)
A26: Torebka celofanowa | B26: 14.99 | C26: 100 | E26: 1 | F26: =IF(AND(ISNUMBER(B26),ISNUMBER(C26),N(C26)>0),B26/C26*N(E26),0)
A27: Etykieta (25 arkuszy A4 × 8 etykiet) | B27: 19.99 | C27: 200 | E27: 1 | F27: =IF(AND(ISNUMBER(B27),ISNUMBER(C27),N(C27)>0),B27/C27*N(E27),0)
F28: =IF(AND(ISNUMBER(B28),ISNUMBER(C28),N(C28)>0),B28/C28*N(E28),0)
A29: Opakowanie na jeden baton | F29: =SUM(F26:F28)
A31: Inne koszty partii (zł): papier do pieczenia, prąd, dojazd… | B31: 1
A33: 3. Koszt i cena
A34: Koszt składników na baton | B34: =IF(N(B5)>0,F22/B5,0)
A35: Koszt opakowania na baton | B35: =F29
A36: Inne koszty na baton | B36: =IF(N(B5)>0,N(B31)/B5,0)
A37: KOSZT JEDNEGO BATONA | B37: =B34+B35+B36
A38: Twój narzut na koszt (%) | B38: 1.2 | C38: np. 100% = cena to podwójny koszt
A39: Cena wyliczona (koszt + narzut) | B39: =B37*(1+N(B38))
A40: Cena sugerowana (w górę do 0,50 zł) | B40: =ROUNDUP(B39*2,0)/2
A41: Twoja cena (opcjonalnie – zostaw puste, by użyć sugerowanej)
A42: Cena do obliczeń | B42: =IF(ISNUMBER(B41),B41,B40)
A44: 4. Zysk
A45: Zysk na jednym batonie | B45: =B42-B37 | C45: =IF(B45<0,"UWAGA: cena poniżej kosztu!","")
A46: Marża w cenie (jaka część ceny to zysk) | B46: =IF(B42>0,B45/B42,0)
...

Sheet Mój przepis 2
A1: Kalkulator Ceny w zł
A2: Twój przepis · wypełnij żółte pola
A4: Nazwa przepisu
A5: Liczba batonów z jednej partii
A6: Waga jednego batona (g) – na etykietę
A8: 1. Składniki na jedną partię
A9: Składnik | B9: Cena opakowania (zł) | C9: Wielkość opakowania | D9: Jednostka | E9: Zużyte w partii | F9: Koszt w partii (zł) | G9: Na zamówienie (patrz pkt 5)
F10: =IF(AND(ISNUMBER(B10),ISNUMBER(C10),ISNUMBER(E10),N(C10)>0),B10/C10*E10,0) | G10: =IF(ISNUMBER(E10),E10*$B$54,"")
F11: =IF(AND(ISNUMBER(B11),ISNUMBER(C11),ISNUMBER(E11),N(C11)>0),B11/C11*E11,0) | G11: =IF(ISNUMBER(E11),E11*$B$54,"")
F12: =IF(AND(ISNUMBER(B12),ISNUMBER(C12),ISNUMBER(E12),N(C12)>0),B12/C12*E12,0) | G12: =IF(ISNUMBER(E12),E12*$B$54,"")
F13: =IF(AND(ISNUMBER(B13),ISNUMBER(C13),ISNUMBER(E13),N(C13)>0),B13/C13*E13,0) | G13: =IF(ISNUMBER(E13),E13*$B$54,"")
F14: =IF(AND(ISNUMBER(B14),ISNUMBER(C14),ISNUMBER(E14),N(C14)>0),B14/C14*E14,0) | G14: =IF(ISNUMBER(E14),E14*$B$54,"")
F15: =IF(AND(ISNUMBER(B15),ISNUMBER(C15),ISNUMBER(E15),N(C15)>0),B15/C15*E15,0) | G15: =IF(ISNUMBER(E15),E15*$B$54,"")
F16: =IF(AND(ISNUMBER(B16),ISNUMBER(C16),ISNUMBER(E16),N(C16)>0),B16/C16*E16,0) | G16: =IF(ISNUMBER(E16),E16*$B$54,"")
F17: =IF(AND(ISNUMBER(B17),ISNUMBER(C17),ISNUMBER(E17),N(C17)>0),B17/C17*E17,0) | G17: =IF(ISNUMBER(E17),E17*$B$54,"")
F18: =IF(AND(ISNUMBER(B18),ISNUMBER(C18),ISNUMBER(E18),N(C18)>0),B18/C18*E18,0) | G18: =IF(ISNUMBER(E18),E18*$B$54,"")
F19: =IF(AND(ISNUMBER(B19),ISNUMBER(C19),ISNUMBER(E19),N(C19)>0),B19/C19*E19,0) | G19: =IF(ISNUMBER(E19),E19*$B$54,"")
F20: =IF(AND(ISNUMBER(B20),ISNUMBER(C20),ISNUMBER(E20),N(C20)>0),B20/C20*E20,0) | G20: =IF(ISNUMBER(E20),E20*$B$54,"")
F21: =IF(AND(ISNUMBER(B21),ISNUMBER(C21),ISNUMBER(E21),N(C21)>0),B21/C21*E21,0) | G21: =IF(ISNUMBER(E21),E21*$B$54,"")
A22: Suma składników na partię | F22: =SUM(F10:F21)
A24: 2. Opakowanie i etykieta (na jeden baton)
A25: Element | B25: Cena paczki (zł) | C25: Sztuk w paczce | E25: Ile na 1 baton | F25: Koszt na baton (zł)
E26: 1 | F26: =IF(AND(ISNUMBER(B26),ISNUMBER(C26),N(C26)>0),B26/C26*N(E26),0)
E27: 1 | F27: =IF(AND(ISNUMBER(B27),ISNUMBER(C27),N(C27)>0),B27/C27*N(E27),0)
E28: 1 | F28: =IF(AND(ISNUMBER(B28),ISNUMBER(C28),N(C28)>0),B28/C28*N(E28),0)
A29: Opakowanie na jeden baton | F29: =SUM(F26:F28)
A31: Inne koszty partii (zł): papier do pieczenia, prąd, dojazd…
A33: 3. Koszt i cena
A34: Koszt składników na baton | B34: =IF(N(B5)>0,F22/B5,0)
A35: Koszt opakowania na baton | B35: =F29
A36: Inne koszty na baton | B36: =IF(N(B5)>0,N(B31)/B5,0)
A37: KOSZT JEDNEGO BATONA | B37: =B34+B35+B36
A38: Twój narzut na koszt (%) | B38: 1.2 | C38: np. 100% = cena to podwójny koszt
A39: Cena wyliczona (koszt + narzut) | B39: =B37*(1+N(B38))
A40: Cena sugerowana (w górę do 0,50 zł) | B40: =ROUNDUP(B39*2,0)/2
A41: Twoja cena (opcjonalnie – zostaw puste, by użyć sugerowanej)
A42: Cena do obliczeń | B42: =IF(ISNUMBER(B41),B41,B40)
A44: 4. Zysk
A45: Zysk na jednym batonie | B45: =B42-B37 | C45: =IF(B45<0,"UWAGA: cena poniżej kosztu!","")
A46: Marża w cenie (jaka część ceny to zysk) | B46: =IF(B42>0,B45/B42,0)
...

Sheet Mój przepis 3
A1: Kalkulator Ceny w zł
A2: Twój przepis · wypełnij żółte pola
A4: Nazwa przepisu
A5: Liczba batonów z jednej partii
A6: Waga jednego batona (g) – na etykietę
A8: 1. Składniki na jedną partię
A9: Składnik | B9: Cena opakowania (zł) | C9: Wielkość opakowania | D9: Jednostka | E9: Zużyte w partii | F9: Koszt w partii (zł) | G9: Na zamówienie (patrz pkt 5)
F10: =IF(AND(ISNUMBER(B10),ISNUMBER(C10),ISNUMBER(E10),N(C10)>0),B10/C10*E10,0) | G10: =IF(ISNUMBER(E10),E10*$B$54,"")
F11: =IF(AND(ISNUMBER(B11),ISNUMBER(C11),ISNUMBER(E11),N(C11)>0),B11/C11*E11,0) | G11: =IF(ISNUMBER(E11),E11*$B$54,"")
F12: =IF(AND(ISNUMBER(B12),ISNUMBER(C12),ISNUMBER(E12),N(C12)>0),B12/C12*E12,0) | G12: =IF(ISNUMBER(E12),E12*$B$54,"")
F13: =IF(AND(ISNUMBER(B13),ISNUMBER(C13),ISNUMBER(E13),N(C13)>0),B13/C13*E13,0) | G13: =IF(ISNUMBER(E13),E13*$B$54,"")
F14: =IF(AND(ISNUMBER(B14),ISNUMBER(C14),ISNUMBER(E14),N(C14)>0),B14/C14*E14,0) | G14: =IF(ISNUMBER(E14),E14*$B$54,"")
F15: =IF(AND(ISNUMBER(B15),ISNUMBER(C15),ISNUMBER(E15),N(C15)>0),B15/C15*E15,0) | G15: =IF(ISNUMBER(E15),E15*$B$54,"")
F16: =IF(AND(ISNUMBER(B16),ISNUMBER(C16),ISNUMBER(E16),N(C16)>0),B16/C16*E16,0) | G16: =IF(ISNUMBER(E16),E16*$B$54,"")
F17: =IF(AND(ISNUMBER(B17),ISNUMBER(C17),ISNUMBER(E17),N(C17)>0),B17/C17*E17,0) | G17: =IF(ISNUMBER(E17),E17*$B$54,"")
F18: =IF(AND(ISNUMBER(B18),ISNUMBER(C18),ISNUMBER(E18),N(C18)>0),B18/C18*E18,0) | G18: =IF(ISNUMBER(E18),E18*$B$54,"")
F19: =IF(AND(ISNUMBER(B19),ISNUMBER(C19),ISNUMBER(E19),N(C19)>0),B19/C19*E19,0) | G19: =IF(ISNUMBER(E19),E19*$B$54,"")
F20: =IF(AND(ISNUMBER(B20),ISNUMBER(C20),ISNUMBER(E20),N(C20)>0),B20/C20*E20,0) | G20: =IF(ISNUMBER(E20),E20*$B$54,"")
F21: =IF(AND(ISNUMBER(B21),ISNUMBER(C21),ISNUMBER(E21),N(C21)>0),B21/C21*E21,0) | G21: =IF(ISNUMBER(E21),E21*$B$54,"")
A22: Suma składników na partię | F22: =SUM(F10:F21)
A24: 2. Opakowanie i etykieta (na jeden baton)
A25: Element | B25: Cena paczki (zł) | C25: Sztuk w paczce | E25: Ile na 1 baton | F25: Koszt na baton (zł)
E26: 1 | F26: =IF(AND(ISNUMBER(B26),ISNUMBER(C26),N(C26)>0),B26/C26*N(E26),0)
E27: 1 | F27: =IF(AND(ISNUMBER(B27),ISNUMBER(C27),N(C27)>0),B27/C27*N(E27),0)
E28: 1 | F28: =IF(AND(ISNUMBER(B28),ISNUMBER(C28),N(C28)>0),B28/C28*N(E28),0)
A29: Opakowanie na jeden baton | F29: =SUM(F26:F28)
A31: Inne koszty partii (zł): papier do pieczenia, prąd, dojazd…
A33: 3. Koszt i cena
A34: Koszt składników na baton | B34: =IF(N(B5)>0,F22/B5,0)
A35: Koszt opakowania na baton | B35: =F29
A36: Inne koszty na baton | B36: =IF(N(B5)>0,N(B31)/B5,0)
A37: KOSZT JEDNEGO BATONA | B37: =B34+B35+B36
A38: Twój narzut na koszt (%) | B38: 1.2 | C38: np. 100% = cena to podwójny koszt
A39: Cena wyliczona (koszt + narzut) | B39: =B37*(1+N(B38))
A40: Cena sugerowana (w górę do 0,50 zł) | B40: =ROUNDUP(B39*2,0)/2
A41: Twoja cena (opcjonalnie – zostaw puste, by użyć sugerowanej)
A42: Cena do obliczeń | B42: =IF(ISNUMBER(B41),B41,B40)
A44: 4. Zysk
A45: Zysk na jednym batonie | B45: =B42-B37 | C45: =IF(B45<0,"UWAGA: cena poniżej kosztu!","")
A46: Marża w cenie (jaka część ceny to zysk) | B46: =IF(B42>0,B45/B42,0)
...

Sheet Porównanie
A1: Porównanie przepisów
A3: Arkusz | B3: Przepis | C3: Koszt batona | D3: Cena do obliczeń | E3: Zysk na batonie | F3: Zysk z partii
A4: Kalkulator | B4: =IF('Kalkulator'!B4="","(pusty)",'Kalkulator'!B4) | C4: ='Kalkulator'!B37 | D4: ='Kalkulator'!B42 | E4: ='Kalkulator'!B45 | F4: ='Kalkulator'!B49
A5: Mój przepis 2 | B5: =IF('Mój przepis 2'!B4="","(pusty)",'Mój przepis 2'!B4) | C5: ='Mój przepis 2'!B37 | D5: ='Mój przepis 2'!B42 | E5: ='Mój przepis 2'!B45 | F5: ='Mój przepis 2'!B49
A6: Mój przepis 3 | B6: =IF('Mój przepis 3'!B4="","(pusty)",'Mój przepis 3'!B4) | C6: ='Mój przepis 3'!B37 | D6: ='Mój przepis 3'!B42 | E6: ='Mój przepis 3'!B45 | F6: ='Mój przepis 3'!B49
A8: Arkusz tylko do odczytu – zmieniasz dane w arkuszach przepisów.
