Workbook

Sheet Instrukcja
B1: Kalkulator Partii · Pogotowie Batonowe™
B2: Przelicza składniki przepisu na tyle sztuk, ile potrzebujesz. Bez liczenia na kartce.
B4: JAK UŻYWAĆ (3 kroki)
B5: 1. Przejdź do arkusza „Kalkulator”.
B6: 2. W żółtej komórce „Wybierz przepis” kliknij strzałkę i wybierz przepis z listy.
B7: 3. W żółtej komórce „Ile sztuk?” wybierz 12, 24 albo 48. Potrzebujesz innej liczby? Wybierz „inna” i wpisz ją w żółtej komórce poniżej.
B8: Gotowe: w tabeli zobaczysz ilości na Twoją partię – w szklankach i łyżkach oraz w gramach (tam, gdzie przepis podaje gramy).
B10: CO OZNACZAJĄ KOLORY
B11: Żółte komórki – tu wpisujesz albo wybierasz. Wszystko inne liczy się samo (nie nadpisuj formuł).
B13: SKĄD SĄ DANE
B14: 8 przepisów z „Biblii Batonów Proteinowych” z ilościami dokładnie takimi jak w książce (strona podana w arkuszu „Przepisy”).
B15: „Bazowa liczba sztuk” to dolna granica wydajności z książki (np. „ok. 10–12 batonów” → 10), żeby masy nie zabrakło.
... B36: Listę zakupów na 12, 24 i 48 sztuk znajdziesz też w PDF „Lista Zakupów Hurtowych”.

Sheet Kalkulator
A1: Kalkulator Partii
A2: Wybierz przepis i liczbę sztuk w żółtych komórkach. Reszta liczy się sama.
B3: 1. Wybierz przepis: | C3: Batony owsiano-miodowe | N3: =IFERROR(MATCH($C$3,Przepisy!$B$5:$B$13,0),"") -> 1
B4: 2. Ile sztuk potrzebujesz? | C4: 24
B5: 3. Jeśli wybrałaś „inna” – wpisz liczbę:
B7: Z jednej partii z książki wychodzi: | C7: =IF($N$3="","",INDEX(Przepisy!$C$5:$C$13,$N$3)) -> ok. 10–12 batonów
B8: Kalkulator liczy od (bazowa liczba sztuk): | C8: =IF($N$3="","",INDEX(Przepisy!$D$5:$D$13,$N$3)) -> 10 | D8: =IF($N$3="","",INDEX(Przepisy!$E$5:$E$13,$N$3)) -> batonów
B9: Twoja partia (sztuk): | C9: =IF($C$4="inna",IF($C$5="","",$C$5),$C$4) -> 24 | D9: =D8 -> batonów
B10: Mnożnik przepisu: | C10: =IF(OR($C$8="",$C$9="",N($C$8)=0,N($C$9)=0),"",ROUND($C$9/$C$8,3)) -> 2.4 | E10: =IF($C$10="",IF($C$4="inna","← wpisz liczbę sztuk w komórce C5",""),"")
B11: Wskazówka do przepisu: | C11: =IF($N$3="","",INDEX(Przepisy!$G$5:$G$13,$N$3)) -> Najprostszy przepis – idealny na pierwszą partię.
A13: Lp | B13: Składnik | C13: W przepisie | D13: do | E13: Jednostka | F13: Na Twoją partię | G13: do | H13: Jednostka | I13: Gramy w przepisie | J13: Gramy na Twoją partię | K13: W przybliżeniu | L13: Uwagi
A14: 1 | B14: =IF($N$3="","",IF(INDEX(Przepisy!$C$17:$C$106,($N$3-1)*10+1)="","",INDEX(Przepisy!$C$17:$C$106,($N$3-1)*10+1))) -> Płatki owsiane | C14: =IF($N$3="","",IF(INDEX(Przepisy!$D$17:$D$106,($N$3-1)*10+1)="","",INDEX(Przepisy!$D$17:$D$106,($N$3-1)*10+1))) -> 2 | D14: =IF($N$3="","",IF(INDEX(Przepisy!$E$17:$E$106,($N$3-1)*10+1)="","",INDEX(Przepisy!$E$17:$E$106,($N$3-1)*10+1))) | E14: =IF($N$3="","",IF(INDEX(Przepisy!$F$17:$F$106,($N$3-1)*10+1)="","",INDEX(Przepisy!$F$17:$F$106,($N$3-1)*10+1))) -> szkl. | F14: =IF(OR($C14="",$C$10=""),"",IF($E14="szt.",ROUNDUP($C14*$C$10,0),IF($E14="kropli",ROUND($C14*$C$10,0),ROUND($C14*$C$10*4,0)/4))) -> 4.75 | G14: =IF(OR($D14="",$C$10=""),"",IF($E14="szt.",ROUNDUP($D14*$C$10,0),IF($E14="kropli",ROUND($D14*$C$10,0),ROUND($D14*$C$10*4,0)/4))) | H14: =IF($B14="","",$E14) -> szkl. | I14: =IF($N$3="","",IF(INDEX(Przepisy!$G$17:$G$106,($N$3-1)*10+1)="","",INDEX(Przepisy!$G$17:$G$106,($N$3-1)*10+1))) -> 180 | J14: =IF(OR($I14="",$C$10=""),"",ROUND($I14*$C$10,0)) -> 432 | K14: =IF(OR($F14="",$H14=""),"",IF($H14="szkl.",IF(ROUND(($F14-INT($F14))*16,0)=0,INT($F14)&" szkl.",IF(INT($F14)=0,"",INT($F14)&" szkl. + ")&ROUND(($F14-INT($F14))*16,0)&" łyż."),IF(AND($H14="łyż.",$F14>=16),INT($F14/16)&" szkl. + "&MOD($F14,16)&" łyż.",""))) -> 4 szkl. + 12 łyż. | L14: =IF($N$3="","",IF(INDEX(Przepisy!$H$17:$H$106,($N$3-1)*10+1)="","",INDEX(Przepisy!$H$17:$H$106,($N$3-1)*10+1)))
A15: 2 | B15: =IF($N$3="","",IF(INDEX(Przepisy!$C$17:$C$106,($N$3-1)*10+2)="","",INDEX(Przepisy!$C$17:$C$106,($N$3-1)*10+2))) -> Miód | C15: =IF($N$3="","",IF(INDEX(Przepisy!$D$17:$D$106,($N$3-1)*10+2)="","",INDEX(Przepisy!$D$17:$D$106,($N$3-1)*10+2))) -> 0.5 | D15: =IF($N$3="","",IF(INDEX(Przepisy!$E$17:$E$106,($N$3-1)*10+2)="","",INDEX(Przepisy!$E$17:$E$106,($N$3-1)*10+2))) | E15: =IF($N$3="","",IF(INDEX(Przepisy!$F$17:$F$106,($N$3-1)*10+2)="","",INDEX(Przepisy!$F$17:$F$106,($N$3-1)*10+2))) -> szkl. | F15: =IF(OR($C15="",$C$10=""),"",IF($E15="szt.",ROUNDUP($C15*$C$10,0),IF($E15="kropli",ROUND($C15*$C$10,0),ROUND($C15*$C$10*4,0)/4))) -> 1.25 | G15: =IF(OR($D15="",$C$10=""),"",IF($E15="szt.",ROUNDUP($D15*$C$10,0),IF($E15="kropli",ROUND($D15*$C$10,0),ROUND($D15*$C$10*4,0)/4))) | H15: =IF($B15="","",$E15) -> szkl. | I15: =IF($N$3="","",IF(INDEX(Przepisy!$G$17:$G$106,($N$3-1)*10+2)="","",INDEX(Przepisy!$G$17:$G$106,($N$3-1)*10+2))) -> 170 | J15: =IF(OR($I15="",$C$10=""),"",ROUND($I15*$C$10,0)) -> 408 | K15: =IF(OR($F15="",$H15=""),"",IF($H15="szkl.",IF(ROUND(($F15-INT($F15))*16,0)=0,INT($F15)&" szkl.",IF(INT($F15)=0,"",INT($F15)&" szkl. + ")&ROUND(($F15-INT($F15))*16,0)&" łyż."),IF(AND($H15="łyż.",$F15>=16),INT($F15/16)&" szkl. + "&MOD($F15,16)&" łyż.",""))) -> 1 szkl. + 4 łyż. | L15: =IF($N$3="","",IF(INDEX(Przepisy!$H$17:$H$106,($N$3-1)*10+2)="","",INDEX(Przepisy!$H$17:$H$106,($N$3-1)*10+2)))
A16: 3 | B16: =IF($N$3="","",IF(INDEX(Przepisy!$C$17:$C$106,($N$3-1)*10+3)="","",INDEX(Przepisy!$C$17:$C$106,($N$3-1)*10+3))) -> Masło orzechowe | C16: =IF($N$3="","",IF(INDEX(Przepisy!$D$17:$D$106,($N$3-1)*10+3)="","",INDEX(Przepisy!$D$17:$D$106,($N$3-1)*10+3))) -> 0.25 | D16: =IF($N$3="","",IF(INDEX(Przepisy!$E$17:$E$106,($N$3-1)*10+3)="","",INDEX(Przepisy!$E$17:$E$106,($N$3-1)*10+3))) | E16: =IF($N$3="","",IF(INDEX(Przepisy!$F$17:$F$106,($N$3-1)*10+3)="","",INDEX(Przepisy!$F$17:$F$106,($N$3-1)*10+3))) -> szkl. | F16: =IF(OR($C16="",$C$10=""),"",IF($E16="szt.",ROUNDUP($C16*$C$10,0),IF($E16="kropli",ROUND($C16*$C$10,0),ROUND($C16*$C$10*4,0)/4))) -> 0.5 | G16: =IF(OR($D16="",$C$10=""),"",IF($E16="szt.",ROUNDUP($D16*$C$10,0),IF($E16="kropli",ROUND($D16*$C$10,0),ROUND($D16*$C$10*4,0)/4))) | H16: =IF($B16="","",$E16) -> szkl. | I16: =IF($N$3="","",IF(INDEX(Przepisy!$G$17:$G$106,($N$3-1)*10+3)="","",INDEX(Przepisy!$G$17:$G$106,($N$3-1)*10+3))) -> 65 | J16: =IF(OR($I16="",$C$10=""),"",ROUND($I16*$C$10,0)) -> 156 | K16: =IF(OR($F16="",$H16=""),"",IF($H16="szkl.",IF(ROUND(($F16-INT($F16))*16,0)=0,INT($F16)&" szkl.",IF(INT($F16)=0,"",INT($F16)&" szkl. + ")&ROUND(($F16-INT($F16))*16,0)&" łyż."),IF(AND($H16="łyż.",$F16>=16),INT($F16/16)&" szkl. + "&MOD($F16,16)&" łyż.",""))) -> 8 łyż. | L16: =IF($N$3="","",IF(INDEX(Przepisy!$H$17:$H$106,($N$3-1)*10+3)="","",INDEX(Przepisy!$H$17:$H$106,($N$3-1)*10+3)))
A17: 4 | B17: =IF($N$3="","",IF(INDEX(Przepisy!$C$17:$C$106,($N$3-1)*10+4)="","",INDEX(Przepisy!$C$17:$C$106,($N$3-1)*10+4))) -> Siekane orzechy | C17: =IF($N$3="","",IF(INDEX(Przepisy!$D$17:$D$106,($N$3-1)*10+4)="","",INDEX(Przepisy!$D$17:$D$106,($N$3-1)*10+4))) -> 0.5 | D17: =IF($N$3="","",IF(INDEX(Przepisy!$E$17:$E$106,($N$3-1)*10+4)="","",INDEX(Przepisy!$E$17:$E$106,($N$3-1)*10+4))) | E17: =IF($N$3="","",IF(INDEX(Przepisy!$F$17:$F$106,($N$3-1)*10+4)="","",INDEX(Przepisy!$F$17:$F$106,($N$3-1)*10+4))) -> szkl. | F17: =IF(OR($C17="",$C$10=""),"",IF($E17="szt.",ROUNDUP($C17*$C$10,0),IF($E17="kropli",ROUND($C17*$C$10,0),ROUND($C17*$C$10*4,0)/4))) -> 1.25 | G17: =IF(OR($D17="",$C$10=""),"",IF($E17="szt.",ROUNDUP($D17*$C$10,0),IF($E17="kropli",ROUND($D17*$C$10,0),ROUND($D17*$C$10*4,0)/4))) | H17: =IF($B17="","",$E17) -> szkl. | I17: =IF($N$3="","",IF(INDEX(Przepisy!$G$17:$G$106,($N$3-1)*10+4)="","",INDEX(Przepisy!$G$17:$G$106,($N$3-1)*10+4))) -> 60 | J17: =IF(OR($I17="",$C$10=""),"",ROUND($I17*$C$10,0)) -> 144 | K17: =IF(OR($F17="",$H17=""),"",IF($H17="szkl.",IF(ROUND(($F17-INT($F17))*16,0)=0,INT($F17)&" szkl.",IF(INT($F17)=0,"",INT($F17)&" szkl. + ")&ROUND(($F17-INT($F17))*16,0)&" łyż."),IF(AND($H17="łyż.",$F17>=16),INT($F17/16)&" szkl. + "&MOD($F17,16)&" łyż.",""))) -> 1 szkl. + 4 łyż. | L17: =IF($N$3="","",IF(INDEX(Przepisy!$H$17:$H$106,($N$3-1)*10+4)="","",INDEX(Przepisy!$H$17:$H$106,($N$3-1)*10+4)))
A18: 5 | B18: =IF($N$3="","",IF(INDEX(Przepisy!$C$17:$C$106,($N$3-1)*10+5)="","",INDEX(Przepisy!$C$17:$C$106,($N$3-1)*10+5))) -> Ekstrakt z wanilii | C18: =IF($N$3="","",IF(INDEX(Przepisy!$D$17:$D$106,($N$3-1)*10+5)="","",INDEX(Przepisy!$D$17:$D$106,($N$3-1)*10+5))) -> 1 | D18: =IF($N$3="","",IF(INDEX(Przepisy!$E$17:$E$106,($N$3-1)*10+5)="","",INDEX(Przepisy!$E$17:$E$106,($N$3-1)*10+5))) | E18: =IF($N$3="","",IF(INDEX(Przepisy!$F$17:$F$106,($N$3-1)*10+5)="","",INDEX(Przepisy!$F$17:$F$106,($N$3-1)*10+5))) -> łyżecz. | F18: =IF(OR($C18="",$C$10=""),"",IF($E18="szt.",ROUNDUP($C18*$C$10,0),IF($E18="kropli",ROUND($C18*$C$10,0),ROUND($C18*$C$10*4,0)/4))) -> 2.5 | G18: =IF(OR($D18="",$C$10=""),"",IF($E18="szt.",ROUNDUP($D18*$C$10,0),IF($E18="kropli",ROUND($D18*$C$10,0),ROUND($D18*$C$10*4,0)/4))) | H18: =IF($B18="","",$E18) -> łyżecz. | I18: =IF($N$3="","",IF(INDEX(Przepisy!$G$17:$G$106,($N$3-1)*10+5)="","",INDEX(Przepisy!$G$17:$G$106,($N$3-1)*10+5))) | J18: =IF(OR($I18="",$C$10=""),"",ROUND($I18*$C$10,0)) | K18: =IF(OR($F18="",$H18=""),"",IF($H18="szkl.",IF(ROUND(($F18-INT($F18))*16,0)=0,INT($F18)&" szkl.",IF(INT($F18)=0,"",INT($F18)&" szkl. + ")&ROUND(($F18-INT($F18))*16,0)&" łyż."),IF(AND($H18="łyż.",$F18>=16),INT($F18/16)&" szkl. + "&MOD($F18,16)&" łyż.",""))) | L18: =IF($N$3="","",IF(INDEX(Przepisy!$H$17:$H$106,($N$3-1)*10+5)="","",INDEX(Przepisy!$H$17:$H$106,($N$3-1)*10+5)))
A19: 6 | B19: =IF($N$3="","",IF(INDEX(Przepisy!$C$17:$C$106,($N$3-1)*10+6)="","",INDEX(Przepisy!$C$17:$C$106,($N$3-1)*10+6))) -> Sól | C19: =IF($N$3="","",IF(INDEX(Przepisy!$D$17:$D$106,($N$3-1)*10+6)="","",INDEX(Przepisy!$D$17:$D$106,($N$3-1)*10+6))) -> 1 | D19: =IF($N$3="","",IF(INDEX(Przepisy!$E$17:$E$106,($N$3-1)*10+6)="","",INDEX(Przepisy!$E$17:$E$106,($N$3-1)*10+6))) | E19: =IF($N$3="","",IF(INDEX(Przepisy!$F$17:$F$106,($N$3-1)*10+6)="","",INDEX(Przepisy!$F$17:$F$106,($N$3-1)*10+6))) -> szczypta | F19: =IF(OR($C19="",$C$10=""),"",IF($E19="szt.",ROUNDUP($C19*$C$10,0),IF($E19="kropli",ROUND($C19*$C$10,0),ROUND($C19*$C$10*4,0)/4))) -> 2.5 | G19: =IF(OR($D19="",$C$10=""),"",IF($E19="szt.",ROUNDUP($D19*$C$10,0),IF($E19="kropli",ROUND($D19*$C$10,0),ROUND($D19*$C$10*4,0)/4))) | H19: =IF($B19="","",$E19) -> szczypta | I19: =IF($N$3="","",IF(INDEX(Przepisy!$G$17:$G$106,($N$3-1)*10+6)="","",INDEX(Przepisy!$G$17:$G$106,($N$3-1)*10+6))) | J19: =IF(OR($I19="",$C$10=""),"",ROUND($I19*$C$10,0)) | K19: =IF(OR($F19="",$H19=""),"",IF($H19="szkl.",IF(ROUND(($F19-INT($F19))*16,0)=0,INT($F19)&" szkl.",IF(INT($F19)=0,"",INT($F19)&" szkl. + ")&ROUND(($F19-INT($F19))*16,0)&" łyż."),IF(AND($H19="łyż.",$F19>=16),INT($F19/16)&" szkl. + "&MOD($F19,16)&" łyż.",""))) | L19: =IF($N$3="","",IF(INDEX(Przepisy!$H$17:$H$106,($N$3-1)*10+6)="","",INDEX(Przepisy!$H$17:$H$106,($N$3-1)*10+6))) -> dopraw do smaku
A20: 7 | B20: =IF($N$3="","",IF(INDEX(Przepisy!$C$17:$C$106,($N$3-1)*10+7)="","",INDEX(Przepisy!$C$17:$C$106,($N$3-1)*10+7))) | C20: =IF($N$3="","",IF(INDEX(Przepisy!$D$17:$D$106,($N$3-1)*10+7)="","",INDEX(Przepisy!$D$17:$D$106,($N$3-1)*10+7))) | D20: =IF($N$3="","",IF(INDEX(Przepisy!$E$17:$E$106,($N$3-1)*10+7)="","",INDEX(Przepisy!$E$17:$E$106,($N$3-1)*10+7))) | E20: =IF($N$3="","",IF(INDEX(Przepisy!$F$17:$F$106,($N$3-1)*10+7)="","",INDEX(Przepisy!$F$17:$F$106,($N$3-1)*10+7))) | F20: =IF(OR($C20="",$C$10=""),"",IF($E20="szt.",ROUNDUP($C20*$C$10,0),IF($E20="kropli",ROUND($C20*$C$10,0),ROUND($C20*$C$10*4,0)/4))) | G20: =IF(OR($D20="",$C$10=""),"",IF($E20="szt.",ROUNDUP($D20*$C$10,0),IF($E20="kropli",ROUND($D20*$C$10,0),ROUND($D20*$C$10*4,0)/4))) | H20: =IF($B20="","",$E20) | I20: =IF($N$3="","",IF(INDEX(Przepisy!$G$17:$G$106,($N$3-1)*10+7)="","",INDEX(Przepisy!$G$17:$G$106,($N$3-1)*10+7))) | J20: =IF(OR($I20="",$C$10=""),"",ROUND($I20*$C$10,0)) | K20: =IF(OR($F20="",$H20=""),"",IF($H20="szkl.",IF(ROUND(($F20-INT($F20))*16,0)=0,INT($F20)&" szkl.",IF(INT($F20)=0,"",INT($F20)&" szkl. + ")&ROUND(($F20-INT($F20))*16,0)&" łyż."),IF(AND($H20="łyż.",$F20>=16),INT($F20/16)&" szkl. + "&MOD($F20,16)&" łyż.",""))) | L20: =IF($N$3="","",IF(INDEX(Przepisy!$H$17:$H$106,($N$3-1)*10+7)="","",INDEX(Przepisy!$H$17:$H$106,($N$3-1)*10+7)))
A21: 8 | B21: =IF($N$3="","",IF(INDEX(Przepisy!$C$17:$C$106,($N$3-1)*10+8)="","",INDEX(Przepisy!$C$17:$C$106,($N$3-1)*10+8))) | C21: =IF($N$3="","",IF(INDEX(Przepisy!$D$17:$D$106,($N$3-1)*10+8)="","",INDEX(Przepisy!$D$17:$D$106,($N$3-1)*10+8))) | D21: =IF($N$3="","",IF(INDEX(Przepisy!$E$17:$E$106,($N$3-1)*10+8)="","",INDEX(Przepisy!$E$17:$E$106,($N$3-1)*10+8))) | E21: =IF($N$3="","",IF(INDEX(Przepisy!$F$17:$F$106,($N$3-1)*10+8)="","",INDEX(Przepisy!$F$17:$F$106,($N$3-1)*10+8))) | F21: =IF(OR($C21="",$C$10=""),"",IF($E21="szt.",ROUNDUP($C21*$C$10,0),IF($E21="kropli",ROUND($C21*$C$10,0),ROUND($C21*$C$10*4,0)/4))) | G21: =IF(OR($D21="",$C$10=""),"",IF($E21="szt.",ROUNDUP($D21*$C$10,0),IF($E21="kropli",ROUND($D21*$C$10,0),ROUND($D21*$C$10*4,0)/4))) | H21: =IF($B21="","",$E21) | I21: =IF($N$3="","",IF(INDEX(Przepisy!$G$17:$G$106,($N$3-1)*10+8)="","",INDEX(Przepisy!$G$17:$G$106,($N$3-1)*10+8))) | J21: =IF(OR($I21="",$C$10=""),"",ROUND($I21*$C$10,0)) | K21: =IF(OR($F21="",$H21=""),"",IF($H21="szkl.",IF(ROUND(($F21-INT($F21))*16,0)=0,INT($F21)&" szkl.",IF(INT($F21)=0,"",INT($F21)&" szkl. + ")&ROUND(($F21-INT($F21))*16,0)&" łyż."),IF(AND($H21="łyż.",$F21>=16),INT($F21/16)&" szkl. + "&MOD($F21,16)&" łyż.",""))) | L21: =IF($N$3="","",IF(INDEX(Przepisy!$H$17:$H$106,($N$3-1)*10+8)="","",INDEX(Przepisy!$H$17:$H$106,($N$3-1)*10+8)))
A22: 9 | B22: =IF($N$3="","",IF(INDEX(Przepisy!$C$17:$C$106,($N$3-1)*10+9)="","",INDEX(Przepisy!$C$17:$C$106,($N$3-1)*10+9))) | C22: =IF($N$3="","",IF(INDEX(Przepisy!$D$17:$D$106,($N$3-1)*10+9)="","",INDEX(Przepisy!$D$17:$D$106,($N$3-1)*10+9))) | D22: =IF($N$3="","",IF(INDEX(Przepisy!$E$17:$E$106,($N$3-1)*10+9)="","",INDEX(Przepisy!$E$17:$E$106,($N$3-1)*10+9))) | E22: =IF($N$3="","",IF(INDEX(Przepisy!$F$17:$F$106,($N$3-1)*10+9)="","",INDEX(Przepisy!$F$17:$F$106,($N$3-1)*10+9))) | F22: =IF(OR($C22="",$C$10=""),"",IF($E22="szt.",ROUNDUP($C22*$C$10,0),IF($E22="kropli",ROUND($C22*$C$10,0),ROUND($C22*$C$10*4,0)/4))) | G22: =IF(OR($D22="",$C$10=""),"",IF($E22="szt.",ROUNDUP($D22*$C$10,0),IF($E22="kropli",ROUND($D22*$C$10,0),ROUND($D22*$C$10*4,0)/4))) | H22: =IF($B22="","",$E22) | I22: =IF($N$3="","",IF(INDEX(Przepisy!$G$17:$G$106,($N$3-1)*10+9)="","",INDEX(Przepisy!$G$17:$G$106,($N$3-1)*10+9))) | J22: =IF(OR($I22="",$C$10=""),"",ROUND($I22*$C$10,0)) | K22: =IF(OR($F22="",$H22=""),"",IF($H22="szkl.",IF(ROUND(($F22-INT($F22))*16,0)=0,INT($F22)&" szkl.",IF(INT($F22)=0,"",INT($F22)&" szkl. + ")&ROUND(($F22-INT($F22))*16,0)&" łyż."),IF(AND($H22="łyż.",$F22>=16),INT($F22/16)&" szkl. + "&MOD($F22,16)&" łyż.",""))) | L22: =IF($N$3="","",IF(INDEX(Przepisy!$H$17:$H$106,($N$3-1)*10+9)="","",INDEX(Przepisy!$H$17:$H$106,($N$3-1)*10+9)))
A23: 10 | B23: =IF($N$3="","",IF(INDEX(Przepisy!$C$17:$C$106,($N$3-1)*10+10)="","",INDEX(Przepisy!$C$17:$C$106,($N$3-1)*10+10))) | C23: =IF($N$3="","",IF(INDEX(Przepisy!$D$17:$D$106,($N$3-1)*10+10)="","",INDEX(Przepisy!$D$17:$D$106,($N$3-1)*10+10))) | D23: =IF($N$3="","",IF(INDEX(Przepisy!$E$17:$E$106,($N$3-1)*10+10)="","",INDEX(Przepisy!$E$17:$E$106,($N$3-1)*10+10))) | E23: =IF($N$3="","",IF(INDEX(Przepisy!$F$17:$F$106,($N$3-1)*10+10)="","",INDEX(Przepisy!$F$17:$F$106,($N$3-1)*10+10))) | F23: =IF(OR($C23="",$C$10=""),"",IF($E23="szt.",ROUNDUP($C23*$C$10,0),IF($E23="kropli",ROUND($C23*$C$10,0),ROUND($C23*$C$10*4,0)/4))) | G23: =IF(OR($D23="",$C$10=""),"",IF($E23="szt.",ROUNDUP($D23*$C$10,0),IF($E23="kropli",ROUND($D23*$C$10,0),ROUND($D23*$C$10*4,0)/4))) | H23: =IF($B23="","",$E23) | I23: =IF($N$3="","",IF(INDEX(Przepisy!$G$17:$G$106,($N$3-1)*10+10)="","",INDEX(Przepisy!$G$17:$G$106,($N$3-1)*10+10))) | J23: =IF(OR($I23="",$C$10=""),"",ROUND($I23*$C$10,0)) | K23: =IF(OR($F23="",$H23=""),"",IF($H23="szkl.",IF(ROUND(($F23-INT($F23))*16,0)=0,INT($F23)&" szkl.",IF(INT($F23)=0,"",INT($F23)&" szkl. + ")&ROUND(($F23-INT($F23))*16,0)&" łyż."),IF(AND($H23="łyż.",$F23>=16),INT($F23/16)&" szkl. + "&MOD($F23,16)&" łyż.",""))) | L23: =IF($N$3="","",IF(INDEX(Przepisy!$H$17:$H$106,($N$3-1)*10+10)="","",INDEX(Przepisy!$H$17:$H$106,($N$3-1)*10+10)))
I24: Razem: | J24: =IF($C$10="","",SUM(J14:J23)) -> 1140 | K24: g (tylko składniki z gramaturą)
B26: Zaokrąglenia: ilości do 1/4, sztuki w górę do całych. 1 szklanka ≈ 16 łyżek (przybliżenie). Sól i przyprawy dopraw do smaku.
B27: Większa partia nie tężeje szybciej: ten sam docisk i minimum 2 godziny w lodówce (45 minut w zamrażarce).

Sheet Przepisy
A1: Przepisy – dane do Kalkulatora
A2: Ilości tak jak w „Biblii Batonów Proteinowych”. Żółte komórki możesz zmieniać. Nie zmieniaj układu wierszy.
A4: Nr | B4: Przepis | C4: Wydajność w książce | D4: Bazowa liczba sztuk | E4: Co liczysz | F4: Źródło | G4: Uwaga
A5: 1 | B5: Batony owsiano-miodowe | C5: ok. 10–12 batonów | D5: 10 | E5: batonów | F5: Biblia, str. 21 | G5: Najprostszy przepis – idealny na pierwszą partię.
A6: 2 | B6: Batony daktylowo-orzechowe | C6: ok. 8–10 batonów | D6: 8 | E6: batonów | F6: Biblia, str. 22 | G6: Bez miodu. Daktyle namocz 10 minut w ciepłej wodzie.
A7: 3 | B7: Batony czekoladowo-orzechowe | C7: ok. 10 batonów | D7: 10 | E7: batonów | F7: Biblia, str. 23 | G7: Masę odstaw na 5 minut przed dodaniem czekolady.
A8: 4 | B8: Batony trzech tekstur | C8: ok. 10–12 batonów | D8: 10 | E8: batonów | F8: Biblia, str. 24 | G8: Preparowana quinoa zostawia powietrze – dociskaj szczególnie mocno.
A9: 5 | B9: Zdrowe ciasteczka owsiano-jabłkowe | C9: ok. 14–16 ciasteczek | D9: 14 | E9: ciasteczek | F9: Biblia, str. 28 | G9: Piekarnik 180°C, 15–20 minut. Przy dużej partii piecz kilka blach po kolei.
A10: 6 | B10: Zdrowy chlebek marchewkowy | C10: 1 chlebek, ok. 8–10 kawałków | D10: 8 | E10: kawałków | F10: Biblia, str. 29 | G10: Licz całe chlebki: wybierz „inna” i wpisz 8, 16, 24… (1 chlebek = ok. 8 kawałków). Każdy chlebek piecz w osobnej keksówce, 180°C, 35–40 minut.
A11: 7 | B11: Proste kulki mocy | C11: ok. 14–16 kulek | D11: 14 | E11: kulek | F11: Biblia, str. 30 | G11: Formuj wilgotnymi dłońmi; schłódź co najmniej 30 minut.
A12: 8 | B12: Baton proteinowy z granolą (bonus) | C12: w książce nie podano liczby sztuk | D12: 12 | E12: batonów | F12: Biblia, str. 54–55 | G12: To część 2 przepisu. Granolę (część 1) robisz osobno – jedna porcja wystarcza na kilka partii. Liczba 12 sztuk to tylko przykład: wpisz w arkuszu „Przepisy”, ile batonów wychodzi Tobie.
A13: 9 | B13: Mój przepis | C13: wpisz | D13: 12 | E13: sztuk | F13: Twój | G13: Twój własny przepis – uzupełnij żółte komórki.
A15: Składniki (10 wierszy na przepis)
A16: Nr przepisu | B16: Lp | C16: Składnik | D16: Ilość | E16: Ilość do (zakres) | F16: Jednostka | G16: Gramy (z książki) | H16: Uwagi
A17: 1 | B17: 1 | C17: Płatki owsiane | D17: 2 | F17: szkl. | G17: 180
A18: 1 | B18: 2 | C18: Miód | D18: 0.5 | F18: szkl. | G18: 170
A19: 1 | B19: 3 | C19: Masło orzechowe | D19: 0.25 | F19: szkl. | G19: 65
A20: 1 | B20: 4 | C20: Siekane orzechy | D20: 0.5 | F20: szkl. | G20: 60
A21: 1 | B21: 5 | C21: Ekstrakt z wanilii | D21: 1 | F21: łyżecz.
A22: 1 | B22: 6 | C22: Sól | D22: 1 | F22: szczypta | H22: dopraw do smaku
A23: 1 | B23: 7
A24: 1 | B24: 8
A25: 1 | B25: 9
A26: 1 | B26: 10
A27: 2 | B27: 1 | C27: Daktyle bez pestek | D27: 1 | F27: szkl. | G27: 150 | H27: sprawdź, czy nie ma pestek
A28: 2 | B28: 2 | C28: Ciepła woda | D28: 2 | F28: łyż. | H28: do namoczenia daktyli
A29: 2 | B29: 3 | C29: Płatki owsiane | D29: 1.5 | F29: szkl. | G29: 135
A30: 2 | B30: 4 | C30: Siekane orzechy | D30: 0.5 | F30: szkl. | G30: 60
A31: 2 | B31: 5 | C31: Rodzynki lub suszona żurawina | D31: 0.25 | F31: szkl. | G31: 36
A32: 2 | B32: 6 | C32: Skórka z cytryny (ile cytryn) | D32: 0.5 | F32: cytryny | H32: opcjonalnie
A33: 2 | B33: 7
A34: 2 | B34: 8
A35: 2 | B35: 9
A36: 2 | B36: 10
A37: 3 | B37: 1 | C37: Płatki owsiane | D37: 2 | F37: szkl. | G37: 180
A38: 3 | B38: 2 | C38: Masło orzechowe | D38: 0.5 | F38: szkl. | G38: 129
A39: 3 | B39: 3 | C39: Miód | D39: 0.3333 | F39: szkl. | G39: 113
A40: 3 | B40: 4 | C40: Kawałki gorzkiej czekolady | D40: 0.3333 | F40: szkl. | G40: 60
A41: 3 | B41: 5 | C41: Siekane orzeszki ziemne | D41: 0.25 | F41: szkl. | G41: 30
A42: 3 | B42: 6 | C42: Sól | D42: 1 | F42: szczypta | H42: dopraw do smaku
...
