Workbook

Sheet Instruções
B1: Calculadora de Fornadas · SOS Barras™
B2: Calcula os ingredientes da receita para as unidades de que precisas. Sem contas no papel.
B4: COMO USAR (3 passos)
B5: 1. Vai à folha «Calculadora».
B6: 2. Na célula amarela «Escolhe a receita», clica na seta e escolhe a receita da lista.
B7: 3. Na célula amarela «Quantas unidades?», escolhe 12, 24 ou 48. Precisas de outro número? Escolhe «outra» e escreve-o na célula amarela de baixo.
B8: Pronto: na tabela vês as quantidades para a tua fornada – em chávenas e colheres e em gramas (quando a receita indica gramas).
B10: O QUE QUEREM DIZER AS CORES
B11: Células amarelas – é aqui que escreves ou escolhes. Tudo o resto é calculado sozinho (não escrevas por cima das fórmulas).
B13: DE ONDE VÊM OS DADOS
B14: 8 receitas de «A Bíblia das Barras Proteicas», com as quantidades exatamente como no livro (página indicada na folha «Receitas»).
B15: O «Número base de unidades» é o limite mínimo de rendimento do livro (p. ex. «cerca de 10–12 barras» → 10), para não faltar mistura.
... B36: A lista de compras para 12, 24 e 48 unidades está também no PDF «Lista de Compras por Grosso».

Sheet Calculadora
A1: Calculadora de Fornadas
A2: Escolhe a receita e o número de unidades nas células amarelas. O resto é calculado sozinho.
B3: 1. Escolhe a receita: | C3: Barras de aveia e mel | N3: =IFERROR(MATCH($C$3,Receitas!$B$5:$B$13,0),"")
B4: 2. Quantas unidades precisas? | C4: 24
B5: 3. Se escolheste «outra» – escreve o número:
B7: Uma fornada do livro dá: | C7: =IF($N$3="","",INDEX(Receitas!$C$5:$C$13,$N$3))
B8: A calculadora conta a partir de (número base): | C8: =IF($N$3="","",INDEX(Receitas!$D$5:$D$13,$N$3)) | D8: =IF($N$3="","",INDEX(Receitas!$E$5:$E$13,$N$3))
B9: A tua fornada (unidades): | C9: =IF($C$4="outra",IF($C$5="","",$C$5),$C$4) | D9: =D8
B10: Multiplicador da receita: | C10: =IF(OR($C$8="",$C$9="",N($C$8)=0,N($C$9)=0),"",ROUND($C$9/$C$8,3)) | E10: =IF($C$10="",IF($C$4="outra","← escreve o número de unidades na célula C5",""),"")
B11: Dica da receita: | C11: =IF($N$3="","",INDEX(Receitas!$G$5:$G$13,$N$3))
A13: N.º | B13: Ingrediente | C13: Na receita | D13: até | E13: Unidade | F13: Para a tua fornada | G13: até | H13: Unidade | I13: Gramas na receita | J13: Gramas para a tua fornada | K13: Aproximadamente | L13: Notas
A14: 1 | B14: =IF($N$3="","",IF(INDEX(Receitas!$C$17:$C$106,($N$3-1)*10+1)="","",INDEX(Receitas!$C$17:$C$106,($N$3-1)*10+1))) | C14: =IF($N$3="","",IF(INDEX(Receitas!$D$17:$D$106,($N$3-1)*10+1)="","",INDEX(Receitas!$D$17:$D$106,($N$3-1)*10+1))) | D14: =IF($N$3="","",IF(INDEX(Receitas!$E$17:$E$106,($N$3-1)*10+1)="","",INDEX(Receitas!$E$17:$E$106,($N$3-1)*10+1))) | E14: =IF($N$3="","",IF(INDEX(Receitas!$F$17:$F$106,($N$3-1)*10+1)="","",INDEX(Receitas!$F$17:$F$106,($N$3-1)*10+1))) | F14: =IF(OR($C14="",$C$10=""),"",IF($E14="un.",ROUNDUP($C14*$C$10,0),IF($E14="gotas",ROUND($C14*$C$10,0),ROUND($C14*$C$10*4,0)/4))) | G14: =IF(OR($D14="",$C$10=""),"",IF($E14="un.",ROUNDUP($D14*$C$10,0),IF($E14="gotas",ROUND($D14*$C$10,0),ROUND($D14*$C$10*4,0)/4))) | H14: =IF($B14="","",$E14) | I14: =IF($N$3="","",IF(INDEX(Receitas!$G$17:$G$106,($N$3-1)*10+1)="","",INDEX(Receitas!$G$17:$G$106,($N$3-1)*10+1))) | J14: =IF(OR($I14="",$C$10=""),"",ROUND($I14*$C$10,0)) | K14: =IF(OR($F14="",$H14=""),"",IF($H14="cháv.",IF(ROUND(($F14-INT($F14))*16,0)=0,INT($F14)&" cháv.",IF(INT($F14)=0,"",INT($F14)&" cháv. + ")&ROUND(($F14-INT($F14))*16,0)&" c. sopa"),IF(AND($H14="c. sopa",$F14>=16),INT($F14/16)&" cháv. + "&MOD($F14,16)&" c. sopa",""))) | L14: =IF($N$3="","",IF(INDEX(Receitas!$H$17:$H$106,($N$3-1)*10+1)="","",INDEX(Receitas!$H$17:$H$106,($N$3-1)*10+1)))
A15: 2 | B15: =IF($N$3="","",IF(INDEX(Receitas!$C$17:$C$106,($N$3-1)*10+2)="","",INDEX(Receitas!$C$17:$C$106,($N$3-1)*10+2))) | C15: =IF($N$3="","",IF(INDEX(Receitas!$D$17:$D$106,($N$3-1)*10+2)="","",INDEX(Receitas!$D$17:$D$106,($N$3-1)*10+2))) | D15: =IF($N$3="","",IF(INDEX(Receitas!$E$17:$E$106,($N$3-1)*10+2)="","",INDEX(Receitas!$E$17:$E$106,($N$3-1)*10+2))) | E15: =IF($N$3="","",IF(INDEX(Receitas!$F$17:$F$106,($N$3-1)*10+2)="","",INDEX(Receitas!$F$17:$F$106,($N$3-1)*10+2))) | F15: =IF(OR($C15="",$C$10=""),"",IF($E15="un.",ROUNDUP($C15*$C$10,0),IF($E15="gotas",ROUND($C15*$C$10,0),ROUND($C15*$C$10*4,0)/4))) | G15: =IF(OR($D15="",$C$10=""),"",IF($E15="un.",ROUNDUP($D15*$C$10,0),IF($E15="gotas",ROUND($D15*$C$10,0),ROUND($D15*$C$10*4,0)/4))) | H15: =IF($B15="","",$E15) | I15: =IF($N$3="","",IF(INDEX(Receitas!$G$17:$G$106,($N$3-1)*10+2)="","",INDEX(Receitas!$G$17:$G$106,($N$3-1)*10+2))) | J15: =IF(OR($I15="",$C$10=""),"",ROUND($I15*$C$10,0)) | K15: =IF(OR($F15="",$H15=""),"",IF($H15="cháv.",IF(ROUND(($F15-INT($F15))*16,0)=0,INT($F15)&" cháv.",IF(INT($F15)=0,"",INT($F15)&" cháv. + ")&ROUND(($F15-INT($F15))*16,0)&" c. sopa"),IF(AND($H15="c. sopa",$F15>=16),INT($F15/16)&" cháv. + "&MOD($F15,16)&" c. sopa",""))) | L15: =IF($N$3="","",IF(INDEX(Receitas!$H$17:$H$106,($N$3-1)*10+2)="","",INDEX(Receitas!$H$17:$H$106,($N$3-1)*10+2)))
A16: 3 | B16: =IF($N$3="","",IF(INDEX(Receitas!$C$17:$C$106,($N$3-1)*10+3)="","",INDEX(Receitas!$C$17:$C$106,($N$3-1)*10+3))) | C16: =IF($N$3="","",IF(INDEX(Receitas!$D$17:$D$106,($N$3-1)*10+3)="","",INDEX(Receitas!$D$17:$D$106,($N$3-1)*10+3))) | D16: =IF($N$3="","",IF(INDEX(Receitas!$E$17:$E$106,($N$3-1)*10+3)="","",INDEX(Receitas!$E$17:$E$106,($N$3-1)*10+3))) | E16: =IF($N$3="","",IF(INDEX(Receitas!$F$17:$F$106,($N$3-1)*10+3)="","",INDEX(Receitas!$F$17:$F$106,($N$3-1)*10+3))) | F16: =IF(OR($C16="",$C$10=""),"",IF($E16="un.",ROUNDUP($C16*$C$10,0),IF($E16="gotas",ROUND($C16*$C$10,0),ROUND($C16*$C$10*4,0)/4))) | G16: =IF(OR($D16="",$C$10=""),"",IF($E16="un.",ROUNDUP($D16*$C$10,0),IF($E16="gotas",ROUND($D16*$C$10,0),ROUND($D16*$C$10*4,0)/4))) | H16: =IF($B16="","",$E16) | I16: =IF($N$3="","",IF(INDEX(Receitas!$G$17:$G$106,($N$3-1)*10+3)="","",INDEX(Receitas!$G$17:$G$106,($N$3-1)*10+3))) | J16: =IF(OR($I16="",$C$10=""),"",ROUND($I16*$C$10,0)) | K16: =IF(OR($F16="",$H16=""),"",IF($H16="cháv.",IF(ROUND(($F16-INT($F16))*16,0)=0,INT($F16)&" cháv.",IF(INT($F16)=0,"",INT($F16)&" cháv. + ")&ROUND(($F16-INT($F16))*16,0)&" c. sopa"),IF(AND($H16="c. sopa",$F16>=16),INT($F16/16)&" cháv. + "&MOD($F16,16)&" c. sopa",""))) | L16: =IF($N$3="","",IF(INDEX(Receitas!$H$17:$H$106,($N$3-1)*10+3)="","",INDEX(Receitas!$H$17:$H$106,($N$3-1)*10+3)))
A17: 4 | B17: =IF($N$3="","",IF(INDEX(Receitas!$C$17:$C$106,($N$3-1)*10+4)="","",INDEX(Receitas!$C$17:$C$106,($N$3-1)*10+4))) | C17: =IF($N$3="","",IF(INDEX(Receitas!$D$17:$D$106,($N$3-1)*10+4)="","",INDEX(Receitas!$D$17:$D$106,($N$3-1)*10+4))) | D17: =IF($N$3="","",IF(INDEX(Receitas!$E$17:$E$106,($N$3-1)*10+4)="","",INDEX(Receitas!$E$17:$E$106,($N$3-1)*10+4))) | E17: =IF($N$3="","",IF(INDEX(Receitas!$F$17:$F$106,($N$3-1)*10+4)="","",INDEX(Receitas!$F$17:$F$106,($N$3-1)*10+4))) | F17: =IF(OR($C17="",$C$10=""),"",IF($E17="un.",ROUNDUP($C17*$C$10,0),IF($E17="gotas",ROUND($C17*$C$10,0),ROUND($C17*$C$10*4,0)/4))) | G17: =IF(OR($D17="",$C$10=""),"",IF($E17="un.",ROUNDUP($D17*$C$10,0),IF($E17="gotas",ROUND($D17*$C$10,0),ROUND($D17*$C$10*4,0)/4))) | H17: =IF($B17="","",$E17) | I17: =IF($N$3="","",IF(INDEX(Receitas!$G$17:$G$106,($N$3-1)*10+4)="","",INDEX(Receitas!$G$17:$G$106,($N$3-1)*10+4))) | J17: =IF(OR($I17="",$C$10=""),"",ROUND($I17*$C$10,0)) | K17: =IF(OR($F17="",$H17=""),"",IF($H17="cháv.",IF(ROUND(($F17-INT($F17))*16,0)=0,INT($F17)&" cháv.",IF(INT($F17)=0,"",INT($F17)&" cháv. + ")&ROUND(($F17-INT($F17))*16,0)&" c. sopa"),IF(AND($H17="c. sopa",$F17>=16),INT($F17/16)&" cháv. + "&MOD($F17,16)&" c. sopa",""))) | L17: =IF($N$3="","",IF(INDEX(Receitas!$H$17:$H$106,($N$3-1)*10+4)="","",INDEX(Receitas!$H$17:$H$106,($N$3-1)*10+4)))
A18: 5 | B18: =IF($N$3="","",IF(INDEX(Receitas!$C$17:$C$106,($N$3-1)*10+5)="","",INDEX(Receitas!$C$17:$C$106,($N$3-1)*10+5))) | C18: =IF($N$3="","",IF(INDEX(Receitas!$D$17:$D$106,($N$3-1)*10+5)="","",INDEX(Receitas!$D$17:$D$106,($N$3-1)*10+5))) | D18: =IF($N$3="","",IF(INDEX(Receitas!$E$17:$E$106,($N$3-1)*10+5)="","",INDEX(Receitas!$E$17:$E$106,($N$3-1)*10+5))) | E18: =IF($N$3="","",IF(INDEX(Receitas!$F$17:$F$106,($N$3-1)*10+5)="","",INDEX(Receitas!$F$17:$F$106,($N$3-1)*10+5))) | F18: =IF(OR($C18="",$C$10=""),"",IF($E18="un.",ROUNDUP($C18*$C$10,0),IF($E18="gotas",ROUND($C18*$C$10,0),ROUND($C18*$C$10*4,0)/4))) | G18: =IF(OR($D18="",$C$10=""),"",IF($E18="un.",ROUNDUP($D18*$C$10,0),IF($E18="gotas",ROUND($D18*$C$10,0),ROUND($D18*$C$10*4,0)/4))) | H18: =IF($B18="","",$E18) | I18: =IF($N$3="","",IF(INDEX(Receitas!$G$17:$G$106,($N$3-1)*10+5)="","",INDEX(Receitas!$G$17:$G$106,($N$3-1)*10+5))) | J18: =IF(OR($I18="",$C$10=""),"",ROUND($I18*$C$10,0)) | K18: =IF(OR($F18="",$H18=""),"",IF($H18="cháv.",IF(ROUND(($F18-INT($F18))*16,0)=0,INT($F18)&" cháv.",IF(INT($F18)=0,"",INT($F18)&" cháv. + ")&ROUND(($F18-INT($F18))*16,0)&" c. sopa"),IF(AND($H18="c. sopa",$F18>=16),INT($F18/16)&" cháv. + "&MOD($F18,16)&" c. sopa",""))) | L18: =IF($N$3="","",IF(INDEX(Receitas!$H$17:$H$106,($N$3-1)*10+5)="","",INDEX(Receitas!$H$17:$H$106,($N$3-1)*10+5)))
A19: 6 | B19: =IF($N$3="","",IF(INDEX(Receitas!$C$17:$C$106,($N$3-1)*10+6)="","",INDEX(Receitas!$C$17:$C$106,($N$3-1)*10+6))) | C19: =IF($N$3="","",IF(INDEX(Receitas!$D$17:$D$106,($N$3-1)*10+6)="","",INDEX(Receitas!$D$17:$D$106,($N$3-1)*10+6))) | D19: =IF($N$3="","",IF(INDEX(Receitas!$E$17:$E$106,($N$3-1)*10+6)="","",INDEX(Receitas!$E$17:$E$106,($N$3-1)*10+6))) | E19: =IF($N$3="","",IF(INDEX(Receitas!$F$17:$F$106,($N$3-1)*10+6)="","",INDEX(Receitas!$F$17:$F$106,($N$3-1)*10+6))) | F19: =IF(OR($C19="",$C$10=""),"",IF($E19="un.",ROUNDUP($C19*$C$10,0),IF($E19="gotas",ROUND($C19*$C$10,0),ROUND($C19*$C$10*4,0)/4))) | G19: =IF(OR($D19="",$C$10=""),"",IF($E19="un.",ROUNDUP($D19*$C$10,0),IF($E19="gotas",ROUND($D19*$C$10,0),ROUND($D19*$C$10*4,0)/4))) | H19: =IF($B19="","",$E19) | I19: =IF($N$3="","",IF(INDEX(Receitas!$G$17:$G$106,($N$3-1)*10+6)="","",INDEX(Receitas!$G$17:$G$106,($N$3-1)*10+6))) | J19: =IF(OR($I19="",$C$10=""),"",ROUND($I19*$C$10,0)) | K19: =IF(OR($F19="",$H19=""),"",IF($H19="cháv.",IF(ROUND(($F19-INT($F19))*16,0)=0,INT($F19)&" cháv.",IF(INT($F19)=0,"",INT($F19)&" cháv. + ")&ROUND(($F19-INT($F19))*16,0)&" c. sopa"),IF(AND($H19="c. sopa",$F19>=16),INT($F19/16)&" cháv. + "&MOD($F19,16)&" c. sopa",""))) | L19: =IF($N$3="","",IF(INDEX(Receitas!$H$17:$H$106,($N$3-1)*10+6)="","",INDEX(Receitas!$H$17:$H$106,($N$3-1)*10+6)))
A20: 7 | B20: =IF($N$3="","",IF(INDEX(Receitas!$C$17:$C$106,($N$3-1)*10+7)="","",INDEX(Receitas!$C$17:$C$106,($N$3-1)*10+7))) | C20: =IF($N$3="","",IF(INDEX(Receitas!$D$17:$D$106,($N$3-1)*10+7)="","",INDEX(Receitas!$D$17:$D$106,($N$3-1)*10+7))) | D20: =IF($N$3="","",IF(INDEX(Receitas!$E$17:$E$106,($N$3-1)*10+7)="","",INDEX(Receitas!$E$17:$E$106,($N$3-1)*10+7))) | E20: =IF($N$3="","",IF(INDEX(Receitas!$F$17:$F$106,($N$3-1)*10+7)="","",INDEX(Receitas!$F$17:$F$106,($N$3-1)*10+7))) | F20: =IF(OR($C20="",$C$10=""),"",IF($E20="un.",ROUNDUP($C20*$C$10,0),IF($E20="gotas",ROUND($C20*$C$10,0),ROUND($C20*$C$10*4,0)/4))) | G20: =IF(OR($D20="",$C$10=""),"",IF($E20="un.",ROUNDUP($D20*$C$10,0),IF($E20="gotas",ROUND($D20*$C$10,0),ROUND($D20*$C$10*4,0)/4))) | H20: =IF($B20="","",$E20) | I20: =IF($N$3="","",IF(INDEX(Receitas!$G$17:$G$106,($N$3-1)*10+7)="","",INDEX(Receitas!$G$17:$G$106,($N$3-1)*10+7))) | J20: =IF(OR($I20="",$C$10=""),"",ROUND($I20*$C$10,0)) | K20: =IF(OR($F20="",$H20=""),"",IF($H20="cháv.",IF(ROUND(($F20-INT($F20))*16,0)=0,INT($F20)&" cháv.",IF(INT($F20)=0,"",INT($F20)&" cháv. + ")&ROUND(($F20-INT($F20))*16,0)&" c. sopa"),IF(AND($H20="c. sopa",$F20>=16),INT($F20/16)&" cháv. + "&MOD($F20,16)&" c. sopa",""))) | L20: =IF($N$3="","",IF(INDEX(Receitas!$H$17:$H$106,($N$3-1)*10+7)="","",INDEX(Receitas!$H$17:$H$106,($N$3-1)*10+7)))
A21: 8 | B21: =IF($N$3="","",IF(INDEX(Receitas!$C$17:$C$106,($N$3-1)*10+8)="","",INDEX(Receitas!$C$17:$C$106,($N$3-1)*10+8))) | C21: =IF($N$3="","",IF(INDEX(Receitas!$D$17:$D$106,($N$3-1)*10+8)="","",INDEX(Receitas!$D$17:$D$106,($N$3-1)*10+8))) | D21: =IF($N$3="","",IF(INDEX(Receitas!$E$17:$E$106,($N$3-1)*10+8)="","",INDEX(Receitas!$E$17:$E$106,($N$3-1)*10+8))) | E21: =IF($N$3="","",IF(INDEX(Receitas!$F$17:$F$106,($N$3-1)*10+8)="","",INDEX(Receitas!$F$17:$F$106,($N$3-1)*10+8))) | F21: =IF(OR($C21="",$C$10=""),"",IF($E21="un.",ROUNDUP($C21*$C$10,0),IF($E21="gotas",ROUND($C21*$C$10,0),ROUND($C21*$C$10*4,0)/4))) | G21: =IF(OR($D21="",$C$10=""),"",IF($E21="un.",ROUNDUP($D21*$C$10,0),IF($E21="gotas",ROUND($D21*$C$10,0),ROUND($D21*$C$10*4,0)/4))) | H21: =IF($B21="","",$E21) | I21: =IF($N$3="","",IF(INDEX(Receitas!$G$17:$G$106,($N$3-1)*10+8)="","",INDEX(Receitas!$G$17:$G$106,($N$3-1)*10+8))) | J21: =IF(OR($I21="",$C$10=""),"",ROUND($I21*$C$10,0)) | K21: =IF(OR($F21="",$H21=""),"",IF($H21="cháv.",IF(ROUND(($F21-INT($F21))*16,0)=0,INT($F21)&" cháv.",IF(INT($F21)=0,"",INT($F21)&" cháv. + ")&ROUND(($F21-INT($F21))*16,0)&" c. sopa"),IF(AND($H21="c. sopa",$F21>=16),INT($F21/16)&" cháv. + "&MOD($F21,16)&" c. sopa",""))) | L21: =IF($N$3="","",IF(INDEX(Receitas!$H$17:$H$106,($N$3-1)*10+8)="","",INDEX(Receitas!$H$17:$H$106,($N$3-1)*10+8)))
A22: 9 | B22: =IF($N$3="","",IF(INDEX(Receitas!$C$17:$C$106,($N$3-1)*10+9)="","",INDEX(Receitas!$C$17:$C$106,($N$3-1)*10+9))) | C22: =IF($N$3="","",IF(INDEX(Receitas!$D$17:$D$106,($N$3-1)*10+9)="","",INDEX(Receitas!$D$17:$D$106,($N$3-1)*10+9))) | D22: =IF($N$3="","",IF(INDEX(Receitas!$E$17:$E$106,($N$3-1)*10+9)="","",INDEX(Receitas!$E$17:$E$106,($N$3-1)*10+9))) | E22: =IF($N$3="","",IF(INDEX(Receitas!$F$17:$F$106,($N$3-1)*10+9)="","",INDEX(Receitas!$F$17:$F$106,($N$3-1)*10+9))) | F22: =IF(OR($C22="",$C$10=""),"",IF($E22="un.",ROUNDUP($C22*$C$10,0),IF($E22="gotas",ROUND($C22*$C$10,0),ROUND($C22*$C$10*4,0)/4))) | G22: =IF(OR($D22="",$C$10=""),"",IF($E22="un.",ROUNDUP($D22*$C$10,0),IF($E22="gotas",ROUND($D22*$C$10,0),ROUND($D22*$C$10*4,0)/4))) | H22: =IF($B22="","",$E22) | I22: =IF($N$3="","",IF(INDEX(Receitas!$G$17:$G$106,($N$3-1)*10+9)="","",INDEX(Receitas!$G$17:$G$106,($N$3-1)*10+9))) | J22: =IF(OR($I22="",$C$10=""),"",ROUND($I22*$C$10,0)) | K22: =IF(OR($F22="",$H22=""),"",IF($H22="cháv.",IF(ROUND(($F22-INT($F22))*16,0)=0,INT($F22)&" cháv.",IF(INT($F22)=0,"",INT($F22)&" cháv. + ")&ROUND(($F22-INT($F22))*16,0)&" c. sopa"),IF(AND($H22="c. sopa",$F22>=16),INT($F22/16)&" cháv. + "&MOD($F22,16)&" c. sopa",""))) | L22: =IF($N$3="","",IF(INDEX(Receitas!$H$17:$H$106,($N$3-1)*10+9)="","",INDEX(Receitas!$H$17:$H$106,($N$3-1)*10+9)))
A23: 10 | B23: =IF($N$3="","",IF(INDEX(Receitas!$C$17:$C$106,($N$3-1)*10+10)="","",INDEX(Receitas!$C$17:$C$106,($N$3-1)*10+10))) | C23: =IF($N$3="","",IF(INDEX(Receitas!$D$17:$D$106,($N$3-1)*10+10)="","",INDEX(Receitas!$D$17:$D$106,($N$3-1)*10+10))) | D23: =IF($N$3="","",IF(INDEX(Receitas!$E$17:$E$106,($N$3-1)*10+10)="","",INDEX(Receitas!$E$17:$E$106,($N$3-1)*10+10))) | E23: =IF($N$3="","",IF(INDEX(Receitas!$F$17:$F$106,($N$3-1)*10+10)="","",INDEX(Receitas!$F$17:$F$106,($N$3-1)*10+10))) | F23: =IF(OR($C23="",$C$10=""),"",IF($E23="un.",ROUNDUP($C23*$C$10,0),IF($E23="gotas",ROUND($C23*$C$10,0),ROUND($C23*$C$10*4,0)/4))) | G23: =IF(OR($D23="",$C$10=""),"",IF($E23="un.",ROUNDUP($D23*$C$10,0),IF($E23="gotas",ROUND($D23*$C$10,0),ROUND($D23*$C$10*4,0)/4))) | H23: =IF($B23="","",$E23) | I23: =IF($N$3="","",IF(INDEX(Receitas!$G$17:$G$106,($N$3-1)*10+10)="","",INDEX(Receitas!$G$17:$G$106,($N$3-1)*10+10))) | J23: =IF(OR($I23="",$C$10=""),"",ROUND($I23*$C$10,0)) | K23: =IF(OR($F23="",$H23=""),"",IF($H23="cháv.",IF(ROUND(($F23-INT($F23))*16,0)=0,INT($F23)&" cháv.",IF(INT($F23)=0,"",INT($F23)&" cháv. + ")&ROUND(($F23-INT($F23))*16,0)&" c. sopa"),IF(AND($H23="c. sopa",$F23>=16),INT($F23/16)&" cháv. + "&MOD($F23,16)&" c. sopa",""))) | L23: =IF($N$3="","",IF(INDEX(Receitas!$H$17:$H$106,($N$3-1)*10+10)="","",INDEX(Receitas!$H$17:$H$106,($N$3-1)*10+10)))
I24: Total: | J24: =IF($C$10="","",SUM(J14:J23)) | K24: g (só ingredientes com peso indicado)
B26: Arredondamentos: quantidades a 1/4, unidades para cima, a inteiras. 1 chávena ≈ 16 colheres de sopa (aproximação). Sal e especiarias a gosto.
B27: Uma fornada maior não firma mais depressa: a mesma pressão e no mínimo 2 horas no frigorífico (45 minutos no congelador).

Sheet Receitas
A1: Receitas – dados para a Calculadora
A2: Quantidades como em «A Bíblia das Barras Proteicas». Podes mudar as células amarelas. Não mudes a ordem das linhas.
A4: N.º | B4: Receita | C4: Rendimento no livro | D4: Número base de unidades | E4: O que contas | F4: Fonte | G4: Nota
A5: 1 | B5: Barras de aveia e mel | C5: cerca de 10–12 barras | D5: 10 | E5: barras | F5: Bíblia, pág. 21 | G5: A receita mais simples – ideal para a primeira fornada.
A6: 2 | B6: Barras de tâmaras e frutos secos | C6: cerca de 8–10 barras | D6: 8 | E6: barras | F6: Bíblia, pág. 22 | G6: Sem mel. Demolha as tâmaras 10 minutos em água morna.
A7: 3 | B7: Barras de chocolate e amendoim | C7: cerca de 10 barras | D7: 10 | E7: barras | F7: Bíblia, pág. 23 | G7: Deixa a mistura arrefecer 5 minutos antes de juntar o chocolate.
A8: 4 | B8: Barras de 3 texturas | C8: cerca de 10–12 barras | D8: 10 | E8: barras | F8: Bíblia, pág. 24 | G8: A quinoa tufada deixa ar – calca com muita força.
A9: 5 | B9: Bolachas de aveia e maçã | C9: cerca de 14–16 bolachas | D9: 14 | E9: bolachas | F9: Bíblia, pág. 28 | G9: Forno a 180 °C, 15–20 minutos. Numa fornada grande, coze vários tabuleiros seguidos.
A10: 6 | B10: Bolo saudável de cenoura | C10: 1 bolo, cerca de 8–10 fatias | D10: 8 | E10: fatias | F10: Bíblia, pág. 29 | G10: Conta bolos inteiros: escolhe «outra» e escreve 8, 16, 24… (1 bolo = cerca de 8 fatias). Coze cada bolo na sua forma de bolo inglês, 180 °C, 35–40 minutos.
A11: 7 | B11: Bolinhas energéticas | C11: cerca de 14–16 bolinhas | D11: 14 | E11: bolinhas | F11: Bíblia, pág. 30 | G11: Molda com as mãos húmidas; leva ao frio pelo menos 30 minutos.
A12: 8 | B12: Barra proteica de granola (bónus) | C12: o livro não indica o número de unidades | D12: 12 | E12: barras | F12: Bíblia, pág. 54–55 | G12: É a parte 2 da receita. A granola (parte 1) fazes à parte – uma dose chega para várias fornadas. As 12 unidades são só um exemplo: escreve na folha «Receitas» quantas barras te saem.
A13: 9 | B13: A minha receita | C13: escreve | D13: 12 | E13: unidades | F13: Tua | G13: A tua própria receita – preenche as células amarelas.
A15: Ingredientes (10 linhas por receita)
A16: N.º receita | B16: N.º | C16: Ingrediente | D16: Quantidade | E16: Quantidade até (intervalo) | F16: Unidade | G16: Gramas (do livro) | H16: Notas
A17: 1 | B17: 1 | C17: Flocos de aveia | D17: 2 | F17: cháv. | G17: 180
A18: 1 | B18: 2 | C18: Mel | D18: 0.5 | F18: cháv. | G18: 170
A19: 1 | B19: 3 | C19: Manteiga de amendoim | D19: 0.25 | F19: cháv. | G19: 65
A20: 1 | B20: 4 | C20: Frutos secos picados | D20: 0.5 | F20: cháv. | G20: 60
A21: 1 | B21: 5 | C21: Extrato de baunilha | D21: 1 | F21: c. chá
A22: 1 | B22: 6 | C22: Sal | D22: 1 | F22: pitada | H22: a gosto
A23: 1 | B23: 7
A24: 1 | B24: 8
A25: 1 | B25: 9
A26: 1 | B26: 10
A27: 2 | B27: 1 | C27: Tâmaras sem caroço | D27: 1 | F27: cháv. | G27: 150 | H27: verifica se não há caroços
A28: 2 | B28: 2 | C28: Água morna | D28: 2 | F28: c. sopa | H28: para demolhar as tâmaras
A29: 2 | B29: 3 | C29: Flocos de aveia | D29: 1.5 | F29: cháv. | G29: 135
A30: 2 | B30: 4 | C30: Frutos secos picados | D30: 0.5 | F30: cháv. | G30: 60
A31: 2 | B31: 5 | C31: Passas ou arandos secos | D31: 0.25 | F31: cháv. | G31: 36
A32: 2 | B32: 6 | C32: Raspa de limão (quantos limões) | D32: 0.5 | F32: limão | H32: opcional
A33: 2 | B33: 7
A34: 2 | B34: 8
A35: 2 | B35: 9
A36: 2 | B36: 10
A37: 3 | B37: 1 | C37: Flocos de aveia | D37: 2 | F37: cháv. | G37: 180
A38: 3 | B38: 2 | C38: Manteiga de amendoim | D38: 0.5 | F38: cháv. | G38: 129
A39: 3 | B39: 3 | C39: Mel | D39: 0.3333 | F39: cháv. | G39: 113
A40: 3 | B40: 4 | C40: Pepitas de chocolate negro | D40: 0.3333 | F40: cháv. | G40: 60
A41: 3 | B41: 5 | C41: Amendoim picado | D41: 0.25 | F41: cháv. | G41: 30
A42: 3 | B42: 6 | C42: Sal | D42: 1 | F42: pitada | H42: a gosto
...
