Workbook

Sheet Instruções
B1: Calculadora de Preço em €
B2: Primeiras Encomendas em 14 Dias™ · quanto te custa mesmo cada barra e por quanto a vender
B4: Como funciona – 6 passos
B5: 1. Vai à folha «Calculadora». Está preenchida com um exemplo: Barras de aveia e mel, do capítulo 4 da Bíblia.
B6: 2. Os preços do exemplo são PREÇOS DE EXEMPLO de um supermercado em Portugal – põe os teus, dos talões.
B7: 3. Só preenches os campos AMARELOS: preço da embalagem, tamanho da embalagem, quanto usaste na fornada, número de barras por fornada.
B8: 4. Junta o custo do saco e do rótulo e os outros custos da fornada (por exemplo papel vegetal).
B9: 5. Escolhe a margem sobre o custo (por exemplo 120%). A calculadora mostra o custo por barra, o preço arredondado para cima aos 0,10 € e o lucro da fornada.
B10: 6. Queres outro preço? Escreve-o no campo «O teu preço». A calculadora refaz o lucro com o teu preço.
B12: Cores dos campos
B13: Campo amarelo = aqui escreves os teus dados.
B14: Campo branco = resultado calculado automaticamente. Não escrevas por cima – tem fórmulas.
... B27: O passo a passo também está no PDF «Como usar a calculadora».

Sheet Calculadora
A1: Calculadora de Preço em €
A2: Exemplo: Barras de aveia e mel (Bíblia, capítulo 4) · PREÇOS DE EXEMPLO, PÕE OS TEUS
A4: Nome da receita | B4: Barras de aveia e mel
A5: Número de barras por fornada | B5: 12
A6: Peso de uma barra (g) – para o rótulo | B6: 40
A8: 1. Ingredientes para uma fornada
A9: Ingrediente | B9: Preço da embalagem (€) | C9: Tamanho da embalagem | D9: Unidade | E9: Usado na fornada | F9: Custo na fornada (€) | G9: Para as encomendas (ver ponto 5)
A10: Flocos de aveia | B10: 1.19 | C10: 500 | D10: g | E10: 180 | F10: =IF(AND(ISNUMBER(B10),ISNUMBER(C10),ISNUMBER(E10),N(C10)>0),B10/C10*E10,0) | G10: =IF(ISNUMBER(E10),E10*$B$54,"")
A11: Mel | B11: 4.99 | C11: 500 | D11: g | E11: 170 | F11: =IF(AND(ISNUMBER(B11),ISNUMBER(C11),ISNUMBER(E11),N(C11)>0),B11/C11*E11,0) | G11: =IF(ISNUMBER(E11),E11*$B$54,"")
A12: Manteiga de amendoim 100% | B12: 3.49 | C12: 350 | D12: g | E12: 65 | F12: =IF(AND(ISNUMBER(B12),ISNUMBER(C12),ISNUMBER(E12),N(C12)>0),B12/C12*E12,0) | G12: =IF(ISNUMBER(E12),E12*$B$54,"")
A13: Nozes (picadas) | B13: 3.29 | C13: 200 | D13: g | E13: 60 | F13: =IF(AND(ISNUMBER(B13),ISNUMBER(C13),ISNUMBER(E13),N(C13)>0),B13/C13*E13,0) | G13: =IF(ISNUMBER(E13),E13*$B$54,"")
A14: Extrato de baunilha | B14: 4.49 | C14: 50 | D14: ml | E14: 5 | F14: =IF(AND(ISNUMBER(B14),ISNUMBER(C14),ISNUMBER(E14),N(C14)>0),B14/C14*E14,0) | G14: =IF(ISNUMBER(E14),E14*$B$54,"")
A15: Sal | B15: 0.45 | C15: 1000 | D15: g | E15: 1 | F15: =IF(AND(ISNUMBER(B15),ISNUMBER(C15),ISNUMBER(E15),N(C15)>0),B15/C15*E15,0) | G15: =IF(ISNUMBER(E15),E15*$B$54,"")
A16: Proteína em pó (se usares) | B16: 24.99 | C16: 700 | D16: g | E16: 0 | F16: =IF(AND(ISNUMBER(B16),ISNUMBER(C16),ISNUMBER(E16),N(C16)>0),B16/C16*E16,0) | G16: =IF(ISNUMBER(E16),E16*$B$54,"")
F17: =IF(AND(ISNUMBER(B17),ISNUMBER(C17),ISNUMBER(E17),N(C17)>0),B17/C17*E17,0) | G17: =IF(ISNUMBER(E17),E17*$B$54,"")
F18: =IF(AND(ISNUMBER(B18),ISNUMBER(C18),ISNUMBER(E18),N(C18)>0),B18/C18*E18,0) | G18: =IF(ISNUMBER(E18),E18*$B$54,"")
F19: =IF(AND(ISNUMBER(B19),ISNUMBER(C19),ISNUMBER(E19),N(C19)>0),B19/C19*E19,0) | G19: =IF(ISNUMBER(E19),E19*$B$54,"")
F20: =IF(AND(ISNUMBER(B20),ISNUMBER(C20),ISNUMBER(E20),N(C20)>0),B20/C20*E20,0) | G20: =IF(ISNUMBER(E20),E20*$B$54,"")
F21: =IF(AND(ISNUMBER(B21),ISNUMBER(C21),ISNUMBER(E21),N(C21)>0),B21/C21*E21,0) | G21: =IF(ISNUMBER(E21),E21*$B$54,"")
A22: Total de ingredientes por fornada | F22: =SUM(F10:F21)
A24: 2. Embalagem e rótulo (por barra)
A25: Elemento | B25: Preço do pacote (€) | C25: Unidades no pacote | E25: Quantas por barra | F25: Custo por barra (€)
A26: Saco de celofane | B26: 4.99 | C26: 100 | E26: 1 | F26: =IF(AND(ISNUMBER(B26),ISNUMBER(C26),N(C26)>0),B26/C26*N(E26),0)
A27: Rótulo (25 folhas A4 × 8 rótulos) | B27: 9.99 | C27: 200 | E27: 1 | F27: =IF(AND(ISNUMBER(B27),ISNUMBER(C27),N(C27)>0),B27/C27*N(E27),0)
F28: =IF(AND(ISNUMBER(B28),ISNUMBER(C28),N(C28)>0),B28/C28*N(E28),0)
A29: Embalagem por barra | F29: =SUM(F26:F28)
A31: Outros custos da fornada (€): papel vegetal, eletricidade, deslocação… | B31: 1
A33: 3. Custo e preço
A34: Custo dos ingredientes por barra | B34: =IF(N(B5)>0,F22/B5,0)
A35: Custo da embalagem por barra | B35: =F29
A36: Outros custos por barra | B36: =IF(N(B5)>0,N(B31)/B5,0)
A37: CUSTO DE UMA BARRA | B37: =B34+B35+B36
A38: A tua margem sobre o custo (%) | B38: 1.2 | C38: p. ex. 100% = o preço é o dobro do custo
A39: Preço calculado (custo + margem) | B39: =B37*(1+N(B38))
A40: Preço sugerido (arredondado para cima, 0,10 €) | B40: =ROUNDUP(B39*10,0)/10
A41: O teu preço (opcional – deixa vazio para usar o sugerido)
A42: Preço usado nas contas | B42: =IF(ISNUMBER(B41),B41,B40)
A44: 4. Lucro
A45: Lucro por barra | B45: =B42-B37 | C45: =IF(B45<0,"ATENÇÃO: preço abaixo do custo!","")
A46: Margem no preço (que parte do preço é lucro) | B46: =IF(B42>0,B45/B42,0)
...

Sheet A minha receita 2
A1: Calculadora de Preço em €
A2: A tua receita · preenche os campos amarelos
A4: Nome da receita
A5: Número de barras por fornada
A6: Peso de uma barra (g) – para o rótulo
A8: 1. Ingredientes para uma fornada
A9: Ingrediente | B9: Preço da embalagem (€) | C9: Tamanho da embalagem | D9: Unidade | E9: Usado na fornada | F9: Custo na fornada (€) | G9: Para as encomendas (ver ponto 5)
F10: =IF(AND(ISNUMBER(B10),ISNUMBER(C10),ISNUMBER(E10),N(C10)>0),B10/C10*E10,0) | G10: =IF(ISNUMBER(E10),E10*$B$54,"")
F11: =IF(AND(ISNUMBER(B11),ISNUMBER(C11),ISNUMBER(E11),N(C11)>0),B11/C11*E11,0) | G11: =IF(ISNUMBER(E11),E11*$B$54,"")
F12: =IF(AND(ISNUMBER(B12),ISNUMBER(C12),ISNUMBER(E12),N(C12)>0),B12/C12*E12,0) | G12: =IF(ISNUMBER(E12),E12*$B$54,"")
F13: =IF(AND(ISNUMBER(B13),ISNUMBER(C13),ISNUMBER(E13),N(C13)>0),B13/C13*E13,0) | G13: =IF(ISNUMBER(E13),E13*$B$54,"")
F14: =IF(AND(ISNUMBER(B14),ISNUMBER(C14),ISNUMBER(E14),N(C14)>0),B14/C14*E14,0) | G14: =IF(ISNUMBER(E14),E14*$B$54,"")
F15: =IF(AND(ISNUMBER(B15),ISNUMBER(C15),ISNUMBER(E15),N(C15)>0),B15/C15*E15,0) | G15: =IF(ISNUMBER(E15),E15*$B$54,"")
F16: =IF(AND(ISNUMBER(B16),ISNUMBER(C16),ISNUMBER(E16),N(C16)>0),B16/C16*E16,0) | G16: =IF(ISNUMBER(E16),E16*$B$54,"")
F17: =IF(AND(ISNUMBER(B17),ISNUMBER(C17),ISNUMBER(E17),N(C17)>0),B17/C17*E17,0) | G17: =IF(ISNUMBER(E17),E17*$B$54,"")
F18: =IF(AND(ISNUMBER(B18),ISNUMBER(C18),ISNUMBER(E18),N(C18)>0),B18/C18*E18,0) | G18: =IF(ISNUMBER(E18),E18*$B$54,"")
F19: =IF(AND(ISNUMBER(B19),ISNUMBER(C19),ISNUMBER(E19),N(C19)>0),B19/C19*E19,0) | G19: =IF(ISNUMBER(E19),E19*$B$54,"")
F20: =IF(AND(ISNUMBER(B20),ISNUMBER(C20),ISNUMBER(E20),N(C20)>0),B20/C20*E20,0) | G20: =IF(ISNUMBER(E20),E20*$B$54,"")
F21: =IF(AND(ISNUMBER(B21),ISNUMBER(C21),ISNUMBER(E21),N(C21)>0),B21/C21*E21,0) | G21: =IF(ISNUMBER(E21),E21*$B$54,"")
A22: Total de ingredientes por fornada | F22: =SUM(F10:F21)
A24: 2. Embalagem e rótulo (por barra)
A25: Elemento | B25: Preço do pacote (€) | C25: Unidades no pacote | E25: Quantas por barra | F25: Custo por barra (€)
E26: 1 | F26: =IF(AND(ISNUMBER(B26),ISNUMBER(C26),N(C26)>0),B26/C26*N(E26),0)
E27: 1 | F27: =IF(AND(ISNUMBER(B27),ISNUMBER(C27),N(C27)>0),B27/C27*N(E27),0)
E28: 1 | F28: =IF(AND(ISNUMBER(B28),ISNUMBER(C28),N(C28)>0),B28/C28*N(E28),0)
A29: Embalagem por barra | F29: =SUM(F26:F28)
A31: Outros custos da fornada (€): papel vegetal, eletricidade, deslocação…
A33: 3. Custo e preço
A34: Custo dos ingredientes por barra | B34: =IF(N(B5)>0,F22/B5,0)
A35: Custo da embalagem por barra | B35: =F29
A36: Outros custos por barra | B36: =IF(N(B5)>0,N(B31)/B5,0)
A37: CUSTO DE UMA BARRA | B37: =B34+B35+B36
A38: A tua margem sobre o custo (%) | B38: 1.2 | C38: p. ex. 100% = o preço é o dobro do custo
A39: Preço calculado (custo + margem) | B39: =B37*(1+N(B38))
A40: Preço sugerido (arredondado para cima, 0,10 €) | B40: =ROUNDUP(B39*10,0)/10
A41: O teu preço (opcional – deixa vazio para usar o sugerido)
A42: Preço usado nas contas | B42: =IF(ISNUMBER(B41),B41,B40)
A44: 4. Lucro
A45: Lucro por barra | B45: =B42-B37 | C45: =IF(B45<0,"ATENÇÃO: preço abaixo do custo!","")
A46: Margem no preço (que parte do preço é lucro) | B46: =IF(B42>0,B45/B42,0)
...

Sheet A minha receita 3
A1: Calculadora de Preço em €
A2: A tua receita · preenche os campos amarelos
A4: Nome da receita
A5: Número de barras por fornada
A6: Peso de uma barra (g) – para o rótulo
A8: 1. Ingredientes para uma fornada
A9: Ingrediente | B9: Preço da embalagem (€) | C9: Tamanho da embalagem | D9: Unidade | E9: Usado na fornada | F9: Custo na fornada (€) | G9: Para as encomendas (ver ponto 5)
F10: =IF(AND(ISNUMBER(B10),ISNUMBER(C10),ISNUMBER(E10),N(C10)>0),B10/C10*E10,0) | G10: =IF(ISNUMBER(E10),E10*$B$54,"")
F11: =IF(AND(ISNUMBER(B11),ISNUMBER(C11),ISNUMBER(E11),N(C11)>0),B11/C11*E11,0) | G11: =IF(ISNUMBER(E11),E11*$B$54,"")
F12: =IF(AND(ISNUMBER(B12),ISNUMBER(C12),ISNUMBER(E12),N(C12)>0),B12/C12*E12,0) | G12: =IF(ISNUMBER(E12),E12*$B$54,"")
F13: =IF(AND(ISNUMBER(B13),ISNUMBER(C13),ISNUMBER(E13),N(C13)>0),B13/C13*E13,0) | G13: =IF(ISNUMBER(E13),E13*$B$54,"")
F14: =IF(AND(ISNUMBER(B14),ISNUMBER(C14),ISNUMBER(E14),N(C14)>0),B14/C14*E14,0) | G14: =IF(ISNUMBER(E14),E14*$B$54,"")
F15: =IF(AND(ISNUMBER(B15),ISNUMBER(C15),ISNUMBER(E15),N(C15)>0),B15/C15*E15,0) | G15: =IF(ISNUMBER(E15),E15*$B$54,"")
F16: =IF(AND(ISNUMBER(B16),ISNUMBER(C16),ISNUMBER(E16),N(C16)>0),B16/C16*E16,0) | G16: =IF(ISNUMBER(E16),E16*$B$54,"")
F17: =IF(AND(ISNUMBER(B17),ISNUMBER(C17),ISNUMBER(E17),N(C17)>0),B17/C17*E17,0) | G17: =IF(ISNUMBER(E17),E17*$B$54,"")
F18: =IF(AND(ISNUMBER(B18),ISNUMBER(C18),ISNUMBER(E18),N(C18)>0),B18/C18*E18,0) | G18: =IF(ISNUMBER(E18),E18*$B$54,"")
F19: =IF(AND(ISNUMBER(B19),ISNUMBER(C19),ISNUMBER(E19),N(C19)>0),B19/C19*E19,0) | G19: =IF(ISNUMBER(E19),E19*$B$54,"")
F20: =IF(AND(ISNUMBER(B20),ISNUMBER(C20),ISNUMBER(E20),N(C20)>0),B20/C20*E20,0) | G20: =IF(ISNUMBER(E20),E20*$B$54,"")
F21: =IF(AND(ISNUMBER(B21),ISNUMBER(C21),ISNUMBER(E21),N(C21)>0),B21/C21*E21,0) | G21: =IF(ISNUMBER(E21),E21*$B$54,"")
A22: Total de ingredientes por fornada | F22: =SUM(F10:F21)
A24: 2. Embalagem e rótulo (por barra)
A25: Elemento | B25: Preço do pacote (€) | C25: Unidades no pacote | E25: Quantas por barra | F25: Custo por barra (€)
E26: 1 | F26: =IF(AND(ISNUMBER(B26),ISNUMBER(C26),N(C26)>0),B26/C26*N(E26),0)
E27: 1 | F27: =IF(AND(ISNUMBER(B27),ISNUMBER(C27),N(C27)>0),B27/C27*N(E27),0)
E28: 1 | F28: =IF(AND(ISNUMBER(B28),ISNUMBER(C28),N(C28)>0),B28/C28*N(E28),0)
A29: Embalagem por barra | F29: =SUM(F26:F28)
A31: Outros custos da fornada (€): papel vegetal, eletricidade, deslocação…
A33: 3. Custo e preço
A34: Custo dos ingredientes por barra | B34: =IF(N(B5)>0,F22/B5,0)
A35: Custo da embalagem por barra | B35: =F29
A36: Outros custos por barra | B36: =IF(N(B5)>0,N(B31)/B5,0)
A37: CUSTO DE UMA BARRA | B37: =B34+B35+B36
A38: A tua margem sobre o custo (%) | B38: 1.2 | C38: p. ex. 100% = o preço é o dobro do custo
A39: Preço calculado (custo + margem) | B39: =B37*(1+N(B38))
A40: Preço sugerido (arredondado para cima, 0,10 €) | B40: =ROUNDUP(B39*10,0)/10
A41: O teu preço (opcional – deixa vazio para usar o sugerido)
A42: Preço usado nas contas | B42: =IF(ISNUMBER(B41),B41,B40)
A44: 4. Lucro
A45: Lucro por barra | B45: =B42-B37 | C45: =IF(B45<0,"ATENÇÃO: preço abaixo do custo!","")
A46: Margem no preço (que parte do preço é lucro) | B46: =IF(B42>0,B45/B42,0)
...

Sheet Comparação
A1: Comparação de receitas
A3: Folha | B3: Receita | C3: Custo da barra | D3: Preço usado nas contas | E3: Lucro por barra | F3: Lucro da fornada
A4: Calculadora | B4: =IF('Calculadora'!B4="","(vazia)",'Calculadora'!B4) | C4: ='Calculadora'!B37 | D4: ='Calculadora'!B42 | E4: ='Calculadora'!B45 | F4: ='Calculadora'!B49
A5: A minha receita 2 | B5: =IF('A minha receita 2'!B4="","(vazia)",'A minha receita 2'!B4) | C5: ='A minha receita 2'!B37 | D5: ='A minha receita 2'!B42 | E5: ='A minha receita 2'!B45 | F5: ='A minha receita 2'!B49
A6: A minha receita 3 | B6: =IF('A minha receita 3'!B4="","(vazia)",'A minha receita 3'!B4) | C6: ='A minha receita 3'!B37 | D6: ='A minha receita 3'!B42 | E6: ='A minha receita 3'!B45 | F6: ='A minha receita 3'!B49
A8: Folha só de leitura – os dados mudam-se nas folhas das receitas.
